Workbook
Name BIENNE: 'Dependent (INDIRECT)'!$A$2:$A$11
Name Cantons: 'Dropdown from range'!$K$2
Name Countries: 'Dropdown from range'!$K$2
Name data: [1]Temperature!$B$2:$NB$19
Name GENEVE: 'Dependent (INDIRECT)'!$C$2:$C$14
Name LAUSANNE: 'Dependent (INDIRECT)'!$B$2:$B$10
Name traductionzone: TRAD!$A$1:$K$203
Name Traduire: _xlfn.LAMBDA(_xlpm.lig, INDEX(traductionzone, _xlpm.lig, 1+TRAD!$B$1))

Sheet TRAD
A1: ENGLISH | B1: 1
A2: FRANCAIS | B2: Exercise files for conditional formatting | C2: Fichier d'exercices sur la mise en forme conditionnelle | E2: {=IF(ISBLANK(Traduire(ROW())),"",Traduire(ROW()))} -> Exercise files for conditional formatting
E3: {=IF(ISBLANK(Traduire(ROW())),"",Traduire(ROW()))}
B4: Form1 | E4: {=IF(ISBLANK(Traduire(ROW())),"",Traduire(ROW()))} -> Form1
B5: 1.Only text entries are formatted | C5: 1. Seul les textes sont formatés | E5: {=IF(ISBLANK(Traduire(ROW())),"",Traduire(ROW()))} -> 1.Only text entries are formatted
B6: 2. Row Highlight | C6: 2. Ligne en surbrillance | E6: {=IF(ISBLANK(Traduire(ROW())),"",Traduire(ROW()))} -> 2. Row Highlight
B7: 3. The Total appears only when all four inputs are entered. | C7: 3. Le total apparait lorsque les 4 valeurs sont saisies. | E7: {=IF(ISBLANK(Traduire(ROW())),"",Traduire(ROW()))} -> 3. The Total appears only when all four inputs are entered.
B8: 4.Alternate row formatting | C8: 4.Lignes à bande | E8: {=IF(ISBLANK(Traduire(ROW())),"",Traduire(ROW()))} -> 4.Alternate row formatting
E9: {=IF(ISBLANK(Traduire(ROW())),"",Traduire(ROW()))}
B10: 6. Groups of four rows are shaded | C10: 6. Groupe de 4 lignes | E10: {=IF(ISBLANK(Traduire(ROW())),"",Traduire(ROW()))} -> 6. Groups of four rows are shaded
B11: 7. OR condition | C11: 7. Condition OU() | E11: {=IF(ISBLANK(Traduire(ROW())),"",Traduire(ROW()))} -> 7. OR condition
E12: {=IF(ISBLANK(Traduire(ROW())),"",Traduire(ROW()))}
E13: {=IF(ISBLANK(Traduire(ROW())),"",Traduire(ROW()))}
E14: {=IF(ISBLANK(Traduire(ROW())),"",Traduire(ROW()))}
B15: Form2 | E15: {=IF(ISBLANK(Traduire(ROW())),"",Traduire(ROW()))} -> Form2
B16: 1.Only values that match C1 are formatted | C16: 1. Seules les valeurs égales à C1 sont formattées | E16: {=IF(ISBLANK(Traduire(ROW())),"",Traduire(ROW()))} -> 1.Only values that match C1 are formatted
B17: 2.Weekends are formatted | C17: 2. Les weekends sont formatés | E17: {=IF(ISBLANK(Traduire(ROW())),"",Traduire(ROW()))} -> 2.Weekends are formatted
B18: 3. Checkerboard | C18: 3. Echiquier | E18: {=IF(ISBLANK(Traduire(ROW())),"",Traduire(ROW()))} -> 3. Checkerboard
B19: <-- Value to highlight | C19: <-- Valeur à mettre en surbrillance | E19: {=IF(ISBLANK(Traduire(ROW())),"",Traduire(ROW()))} -> <-- Value to highlight
E20: {=IF(ISBLANK(Traduire(ROW())),"",Traduire(ROW()))}
B21: Colors 1 | E21: {=IF(ISBLANK(Traduire(ROW())),"",Traduire(ROW()))} -> Colors 1
B22: A single conditional formatting rule | C22: Régle de MEFC unique pour toutes les cellules | E22: {=IF(ISBLANK(Traduire(ROW())),"",Traduire(ROW()))} -> A single conditional formatting rule
B23: A separate rule for each region | C23: Une règle par région | E23: {=IF(ISBLANK(Traduire(ROW())),"",Traduire(ROW()))} -> A separate rule for each region
B24: Month | C24: Mois | E24: {=IF(ISBLANK(Traduire(ROW())),"",Traduire(ROW()))} -> Month
B25: Western | C25: Ouest | E25: {=IF(ISBLANK(Traduire(ROW())),"",Traduire(ROW()))} -> Western
B26: Central | C26: Centre | E26: {=IF(ISBLANK(Traduire(ROW())),"",Traduire(ROW()))} -> Central
B27: Eastern | C27: Est | E27: {=IF(ISBLANK(Traduire(ROW())),"",Traduire(ROW()))} -> Eastern
B28: C: > Average | C28: C: > Moyenne | E28: {=IF(ISBLANK(Traduire(ROW())),"",Traduire(ROW()))} -> C: > Average
B29: Colors3 | E29: {=IF(ISBLANK(Traduire(ROW())),"",Traduire(ROW()))} -> Colors3
B30: Daily Staffing Level | C30: Attendance quotidienne | E30: {=IF(ISBLANK(Traduire(ROW())),"",Traduire(ROW()))} -> Daily Staffing Level
E31: {=IF(ISBLANK(Traduire(ROW())),"",Traduire(ROW()))}
B32: Bar3 | E32: {=IF(ISBLANK(Traduire(ROW())),"",Traduire(ROW()))} -> Bar3
B33: Incoming Calls | C33: Appels entrants | E33: {=IF(ISBLANK(Traduire(ROW())),"",Traduire(ROW()))} -> Incoming Calls
E34: {=IF(ISBLANK(Traduire(ROW())),"",Traduire(ROW()))}
E35: {=IF(ISBLANK(Traduire(ROW())),"",Traduire(ROW()))}
B36: Accept only text entries | C36: Seuls les textes sont acceptés | E36: {=IF(ISBLANK(Traduire(ROW())),"",Traduire(ROW()))} -> Accept only text entries
B37: Accept value only if it is larger than the previous cell | C37: Seules les valeurs plus grandes que la précédente sont acceptées | E37: {=IF(ISBLANK(Traduire(ROW())),"",Traduire(ROW()))} -> Accept value only if it is larger than the previous cell
B38: To find cells with data validation, go to Home > Find & replace > Go to Special > Data validation | C38: Pour trouver les cellules avec validation de données: Accueil > Rechercher > Rechercher spécial > Validation de données | E38: {=IF(ISBLANK(Traduire(ROW())),"",Traduire(ROW()))} -> To find cells with data validation, go to Home > Find & replace > Go to Special > Data validation
B39: Liist of words inside the rule | C39: Liste déroulante saisie dans la règle | E39: {=IF(ISBLANK(Traduire(ROW())),"",Traduire(ROW()))} -> Liist of words inside the rule
B40: Only dates between 2020 and 2025 | C40: Seulement des dates entre 2020 et 2025 | E40: {=IF(ISBLANK(Traduire(ROW())),"",Traduire(ROW()))} -> Only dates between 2020 and 2025
...

Sheet HP
E17: {=Traduire(2)} -> Exercise files for conditional formatting

Sheet Colors1
B2: A | C2: B | D2: C
A3: =TRAD!$E$24 -> Month | B3: =TRAD!$E$25 -> Western | C3: =TRAD!$E$26 -> Central | D3: =TRAD!$E$27 -> Eastern | F3: A: > | G3: 195000 | N3: 205540 | O3: 103832 | P3: 225732
A4: 1 | B4: 205540 | C4: 103832 | D4: 225732 | N4: 198872 | O4: 98770 | P4: 217073
A5: 2 | B5: =B4+RANDBETWEEN(-10000,11000) -> 201861 | C5: =C4+RANDBETWEEN(-7000,5000) -> 100805 | D5: =D4+RANDBETWEEN(-17000,15000) -> 232756 | F5: B : Top 3 | N5: 197288 | O5: 101020 | P5: 216033
A6: 3 | B6: =B5+RANDBETWEEN(-10000,11000) -> 202717 | C6: =C5+RANDBETWEEN(-7000,5000) -> 98721 | D6: =D5+RANDBETWEEN(-17000,15000) -> 235043 | N6: 187525 | O6: 95176 | P6: 207282
A7: 4 | B7: =B6+RANDBETWEEN(-10000,11000) -> 205730 | C7: =C6+RANDBETWEEN(-7000,5000) -> 102698 | D7: =D6+RANDBETWEEN(-17000,15000) -> 249054 | F7: =TRAD!$E$28 -> C: > Average | N7: 188461 | O7: 96674 | P7: 212904
A8: 5 | B8: =B7+RANDBETWEEN(-10000,11000) -> 215051 | C8: =C7+RANDBETWEEN(-7000,5000) -> 99776 | D8: =D7+RANDBETWEEN(-17000,15000) -> 233219 | N8: 183303 | O8: 95006 | P8: 216793
A9: 6 | B9: =B8+RANDBETWEEN(-10000,11000) -> 208772 | C9: =C8+RANDBETWEEN(-7000,5000) -> 102227 | D9: =D8+RANDBETWEEN(-17000,15000) -> 237760 | N9: 186557 | O9: 97779 | P9: 220331
A10: 7 | B10: =B9+RANDBETWEEN(-10000,11000) -> 213889 | C10: =C9+RANDBETWEEN(-7000,5000) -> 105599 | D10: =D9+RANDBETWEEN(-17000,15000) -> 227835 | N10: 187991 | O10: 96962 | P10: 222856
A11: 8 | B11: =B10+RANDBETWEEN(-10000,11000) -> 208302 | C11: =C10+RANDBETWEEN(-7000,5000) -> 105144 | D11: =D10+RANDBETWEEN(-17000,15000) -> 233577 | N11: 178312 | O11: 93712 | P11: 217776
A12: 9 | B12: =B11+RANDBETWEEN(-10000,11000) -> 214923 | C12: =C11+RANDBETWEEN(-7000,5000) -> 100724 | D12: =D11+RANDBETWEEN(-17000,15000) -> 234870 | N12: 178328 | O12: 89803 | P12: 202666
A13: 10 | B13: =B12+RANDBETWEEN(-10000,11000) -> 207694 | C13: =C12+RANDBETWEEN(-7000,5000) -> 101681 | D13: =D12+RANDBETWEEN(-17000,15000) -> 245041 | N13: 183613 | O13: 83557 | P13: 186072
A14: 11 | B14: =B13+RANDBETWEEN(-10000,11000) -> 203957 | C14: =C13+RANDBETWEEN(-7000,5000) -> 95873 | D14: =D13+RANDBETWEEN(-17000,15000) -> 248265 | N14: 182851 | O14: 86747 | P14: 200313
A15: 12 | B15: =B14+RANDBETWEEN(-10000,11000) -> 204907 | C15: =C14+RANDBETWEEN(-7000,5000) -> 93147 | D15: =D14+RANDBETWEEN(-17000,15000) -> 236656
A18: =TRAD!E22 -> A single conditional formatting rule | F18: =TRAD!E23 -> A separate rule for each region
A20: =TRAD!$E$24 -> Month | B20: =TRAD!$E$25 -> Western | C20: =TRAD!$E$26 -> Central | D20: =TRAD!$E$27 -> Eastern | F20: =A20 -> Month | G20: =B20 -> Western | H20: =C20 -> Central | I20: =D20 -> Eastern | N20: 214030 | O20: 103832 | P20: 225732
A21: 1 | B21: 214030 | C21: 103832 | D21: 225732 | F21: =A21 -> 1 | G21: =B21 -> 214030 | H21: =C21 -> 103832 | I21: =D21 -> 225732 | N21: 217525 | O21: 104597 | P21: 216323
A22: 2 | B22: =B21+RANDBETWEEN(-10000,11000) -> 216711 | C22: =C21+RANDBETWEEN(-7000,5000) -> 107153 | D22: =D21+RANDBETWEEN(-17000,15000) -> 231693 | F22: =A22 -> 2 | G22: =B22 -> 216711 | H22: =C22 -> 107153 | I22: =D22 -> 231693 | N22: 225768 | O22: 101355 | P22: 207688
A23: 3 | B23: =B22+RANDBETWEEN(-10000,11000) -> 220154 | C23: =C22+RANDBETWEEN(-7000,5000) -> 100645 | D23: =D22+RANDBETWEEN(-17000,15000) -> 219372 | F23: =A23 -> 3 | G23: =B23 -> 220154 | H23: =C23 -> 100645 | I23: =D23 -> 219372 | N23: 232322 | O23: 99613 | P23: 220159
A24: 4 | B24: =B23+RANDBETWEEN(-10000,11000) -> 222480 | C24: =C23+RANDBETWEEN(-7000,5000) -> 102778 | D24: =D23+RANDBETWEEN(-17000,15000) -> 226733 | F24: =A24 -> 4 | G24: =B24 -> 222480 | H24: =C24 -> 102778 | I24: =D24 -> 226733 | N24: 241616 | O24: 101747 | P24: 217577
A25: 5 | B25: =B24+RANDBETWEEN(-10000,11000) -> 217850 | C25: =C24+RANDBETWEEN(-7000,5000) -> 101148 | D25: =D24+RANDBETWEEN(-17000,15000) -> 213162 | F25: =A25 -> 5 | G25: =B25 -> 217850 | H25: =C25 -> 101148 | I25: =D25 -> 213162 | N25: 252433 | O25: 100098 | P25: 229492
A26: 6 | B26: =B25+RANDBETWEEN(-10000,11000) -> 224367 | C26: =C25+RANDBETWEEN(-7000,5000) -> 99746 | D26: =D25+RANDBETWEEN(-17000,15000) -> 205141 | F26: =A26 -> 6 | G26: =B26 -> 224367 | H26: =C26 -> 99746 | I26: =D26 -> 205141 | N26: 252815 | O26: 101430 | P26: 240044
A27: 7 | B27: =B26+RANDBETWEEN(-10000,11000) -> 221919 | C27: =C26+RANDBETWEEN(-7000,5000) -> 103869 | D27: =D26+RANDBETWEEN(-17000,15000) -> 199218 | F27: =A27 -> 7 | G27: =B27 -> 221919 | H27: =C27 -> 103869 | I27: =D27 -> 199218 | N27: 255217 | O27: 96869 | P27: 234742
A28: 8 | B28: =B27+RANDBETWEEN(-10000,11000) -> 232789 | C28: =C27+RANDBETWEEN(-7000,5000) -> 105825 | D28: =D27+RANDBETWEEN(-17000,15000) -> 209461 | F28: =A28 -> 8 | G28: =B28 -> 232789 | H28: =C28 -> 105825 | I28: =D28 -> 209461 | N28: 258302 | O28: 101610 | P28: 229942
A29: 9 | B29: =B28+RANDBETWEEN(-10000,11000) -> 226494 | C29: =C28+RANDBETWEEN(-7000,5000) -> 103561 | D29: =D28+RANDBETWEEN(-17000,15000) -> 210942 | F29: =A29 -> 9 | G29: =B29 -> 226494 | H29: =C29 -> 103561 | I29: =D29 -> 210942 | N29: 264761 | O29: 96601 | P29: 219642
A30: 10 | B30: =B29+RANDBETWEEN(-10000,11000) -> 230595 | C30: =C29+RANDBETWEEN(-7000,5000) -> 105091 | D30: =D29+RANDBETWEEN(-17000,15000) -> 221378 | F30: =A30 -> 10 | G30: =B30 -> 230595 | H30: =C30 -> 105091 | I30: =D30 -> 221378 | N30: 274390 | O30: 90634 | P30: 205179
A31: 11 | B31: =B30+RANDBETWEEN(-10000,11000) -> 231352 | C31: =C30+RANDBETWEEN(-7000,5000) -> 98436 | D31: =D30+RANDBETWEEN(-17000,15000) -> 212605 | F31: =A31 -> 11 | G31: =B31 -> 231352 | H31: =C31 -> 98436 | I31: =D31 -> 212605 | N31: 270162 | O31: 86028 | P31: 201000
A32: 12 | B32: =B31+RANDBETWEEN(-10000,11000) -> 226056 | C32: =C31+RANDBETWEEN(-7000,5000) -> 99794 | D32: =D31+RANDBETWEEN(-17000,15000) -> 207270 | F32: =A32 -> 12 | G32: =B32 -> 226056 | H32: =C32 -> 99794 | I32: =D32 -> 207270

Sheet Colors2
A1: Heat map of SIN + COS
A2: 0 | B2: =A2+0.04 -> 0.04 | C2: =B2+0.04 -> 0.08 | D2: =C2+0.04 -> 0.12 | E2: =D2+0.04 -> 0.16 | F2: =E2+0.04 -> 0.2 | G2: =F2+0.04 -> 0.24 | H2: =G2+0.04 -> 0.28 | I2: =H2+0.04 -> 0.32 | ... CW2: =CV2+0.04 -> 4
A3: =A2+0.04 -> 0.04 | B3: =SIN($A3)+COS(B$2) -> 1.0391894 | C3: =SIN($A3)+COS(C$2) -> 1.036791 | D3: =SIN($A3)+COS(D$2) -> 1.032798 | E3: =SIN($A3)+COS(E$2) -> 1.0272166 | F3: =SIN($A3)+COS(F$2) -> 1.0200559 | G3: =SIN($A3)+COS(G$2) -> 1.0113273 | H3: =SIN($A3)+COS(H$2) -> 1.0010448 | I3: =SIN($A3)+COS(I$2) -> 0.98922475 | ... CW3: =SIN($A3)+COS(CW$2) -> -0.61365429
A4: =A3+0.04 -> 0.08 | B4: =SIN($A4)+COS(B$2) -> 1.0791148 | C4: =SIN($A4)+COS(C$2) -> 1.0767164 | D4: =SIN($A4)+COS(D$2) -> 1.0727233 | E4: =SIN($A4)+COS(E$2) -> 1.067142 | F4: =SIN($A4)+COS(F$2) -> 1.0599813 | G4: =SIN($A4)+COS(G$2) -> 1.0512527 | H4: =SIN($A4)+COS(H$2) -> 1.0409701 | I4: =SIN($A4)+COS(I$2) -> 1.0291501 | ... CW4: =SIN($A4)+COS(CW$2) -> -0.57372893
A5: =A4+0.04 -> 0.12 | B5: =SIN($A5)+COS(B$2) -> 1.1189123 | C5: =SIN($A5)+COS(C$2) -> 1.1165139 | D5: =SIN($A5)+COS(D$2) -> 1.1125208 | E5: =SIN($A5)+COS(E$2) -> 1.1069395 | F5: =SIN($A5)+COS(F$2) -> 1.0997788 | G5: =SIN($A5)+COS(G$2) -> 1.0910502 | H5: =SIN($A5)+COS(H$2) -> 1.0807676 | I5: =SIN($A5)+COS(I$2) -> 1.0689476 | ... CW5: =SIN($A5)+COS(CW$2) -> -0.53393141
A6: =A5+0.04 -> 0.16 | B6: =SIN($A6)+COS(B$2) -> 1.1585183 | C6: =SIN($A6)+COS(C$2) -> 1.1561199 | D6: =SIN($A6)+COS(D$2) -> 1.1521268 | E6: =SIN($A6)+COS(E$2) -> 1.1465455 | F6: =SIN($A6)+COS(F$2) -> 1.1393848 | G6: =SIN($A6)+COS(G$2) -> 1.1306562 | H6: =SIN($A6)+COS(H$2) -> 1.1203736 | I6: =SIN($A6)+COS(I$2) -> 1.1085536 | ... CW6: =SIN($A6)+COS(CW$2) -> -0.49432541
A7: =A6+0.04 -> 0.2 | B7: =SIN($A7)+COS(B$2) -> 1.1978694 | C7: =SIN($A7)+COS(C$2) -> 1.195471 | D7: =SIN($A7)+COS(D$2) -> 1.191478 | E7: =SIN($A7)+COS(E$2) -> 1.1858966 | F7: =SIN($A7)+COS(F$2) -> 1.1787359 | G7: =SIN($A7)+COS(G$2) -> 1.1700073 | H7: =SIN($A7)+COS(H$2) -> 1.1597248 | I7: =SIN($A7)+COS(I$2) -> 1.1479047 | ... CW7: =SIN($A7)+COS(CW$2) -> -0.45497429
A8: =A7+0.04 -> 0.24 | B8: =SIN($A8)+COS(B$2) -> 1.2369027 | C8: =SIN($A8)+COS(C$2) -> 1.2345043 | D8: =SIN($A8)+COS(D$2) -> 1.2305113 | E8: =SIN($A8)+COS(E$2) -> 1.2249299 | F8: =SIN($A8)+COS(F$2) -> 1.2177692 | G8: =SIN($A8)+COS(G$2) -> 1.2090406 | H8: =SIN($A8)+COS(H$2) -> 1.1987581 | I8: =SIN($A8)+COS(I$2) -> 1.186938 | ... CW8: =SIN($A8)+COS(CW$2) -> -0.41594099
A9: =A8+0.04 -> 0.28 | B9: =SIN($A9)+COS(B$2) -> 1.2755558 | C9: =SIN($A9)+COS(C$2) -> 1.2731574 | D9: =SIN($A9)+COS(D$2) -> 1.2691643 | E9: =SIN($A9)+COS(E$2) -> 1.2635829 | F9: =SIN($A9)+COS(F$2) -> 1.2564222 | G9: =SIN($A9)+COS(G$2) -> 1.2476936 | H9: =SIN($A9)+COS(H$2) -> 1.2374111 | I9: =SIN($A9)+COS(I$2) -> 1.2255911 | ... CW9: =SIN($A9)+COS(CW$2) -> -0.37728797
A10: =A9+0.04 -> 0.32 | B10: =SIN($A10)+COS(B$2) -> 1.3137667 | C10: =SIN($A10)+COS(C$2) -> 1.3113683 | D10: =SIN($A10)+COS(D$2) -> 1.3073752 | E10: =SIN($A10)+COS(E$2) -> 1.3017938 | F10: =SIN($A10)+COS(F$2) -> 1.2946331 | G10: =SIN($A10)+COS(G$2) -> 1.2859045 | H10: =SIN($A10)+COS(H$2) -> 1.275622 | I10: =SIN($A10)+COS(I$2) -> 1.263802 | ... CW10: =SIN($A10)+COS(CW$2) -> -0.33907706
A11: =A10+0.04 -> 0.36 | B11: =SIN($A11)+COS(B$2) -> 1.3514743 | C11: =SIN($A11)+COS(C$2) -> 1.3490759 | D11: =SIN($A11)+COS(D$2) -> 1.3450829 | E11: =SIN($A11)+COS(E$2) -> 1.3395015 | F11: =SIN($A11)+COS(F$2) -> 1.3323408 | G11: =SIN($A11)+COS(G$2) -> 1.3236122 | H11: =SIN($A11)+COS(H$2) -> 1.3133297 | I11: =SIN($A11)+COS(I$2) -> 1.3015097 | ... CW11: =SIN($A11)+COS(CW$2) -> -0.30136939
A12: =A11+0.04 -> 0.4 | B12: =SIN($A12)+COS(B$2) -> 1.3886184 | C12: =SIN($A12)+COS(C$2) -> 1.38622 | D12: =SIN($A12)+COS(D$2) -> 1.382227 | E12: =SIN($A12)+COS(E$2) -> 1.3766456 | F12: =SIN($A12)+COS(F$2) -> 1.3694849 | G12: =SIN($A12)+COS(G$2) -> 1.3607563 | H12: =SIN($A12)+COS(H$2) -> 1.3504738 | I12: =SIN($A12)+COS(I$2) -> 1.3386538 | ... CW12: =SIN($A12)+COS(CW$2) -> -0.26422528
A13: =A12+0.04 -> 0.44 | B13: =SIN($A13)+COS(B$2) -> 1.4251396 | C13: =SIN($A13)+COS(C$2) -> 1.4227412 | D13: =SIN($A13)+COS(D$2) -> 1.4187481 | E13: =SIN($A13)+COS(E$2) -> 1.4131667 | F13: =SIN($A13)+COS(F$2) -> 1.406006 | G13: =SIN($A13)+COS(G$2) -> 1.3972774 | H13: =SIN($A13)+COS(H$2) -> 1.3869949 | I13: =SIN($A13)+COS(I$2) -> 1.3751749 | ... CW13: =SIN($A13)+COS(CW$2) -> -0.22770416
A14: =A13+0.04 -> 0.48 | B14: =SIN($A14)+COS(B$2) -> 1.4609793 | C14: =SIN($A14)+COS(C$2) -> 1.4585809 | D14: =SIN($A14)+COS(D$2) -> 1.4545878 | E14: =SIN($A14)+COS(E$2) -> 1.4490065 | F14: =SIN($A14)+COS(F$2) -> 1.4418458 | G14: =SIN($A14)+COS(G$2) -> 1.4331172 | H14: =SIN($A14)+COS(H$2) -> 1.4228346 | I14: =SIN($A14)+COS(I$2) -> 1.4110146 | ... CW14: =SIN($A14)+COS(CW$2) -> -0.19186445
... A102: =A101+0.04 -> 4 | B102: =SIN($A102)+COS(B$2) -> 0.24239761 | C102: =SIN($A102)+COS(C$2) -> 0.23999921 | D102: =SIN($A102)+COS(D$2) -> 0.23600614 | E102: =SIN($A102)+COS(E$2) -> 0.23042479 | F102: =SIN($A102)+COS(F$2) -> 0.22326408 | G102: =SIN($A102)+COS(G$2) -> 0.21453548 | H102: =SIN($A102)+COS(H$2) -> 0.20425294 | I102: =SIN($A102)+COS(I$2) -> 0.19243292 | ... CW102: =SIN($A102)+COS(CW$2) -> -1.4104461

Sheet Colors3
A1: =TRAD!E30 -> Daily Staffing Level
A3: =TRAD!E24 -> Month | B3: 1 | C3: =B3+1 -> 2 | D3: =C3+1 -> 3 | E3: =D3+1 -> 4 | F3: =E3+1 -> 5 | G3: =F3+1 -> 6 | H3: =G3+1 -> 7 | I3: =H3+1 -> 8 | J3: =I3+1 -> 9 | ... AF3: =AE3+1 -> 31
A4: 1 | B4: 80 | C4: 80 | D4: 80 | E4: 80 | F4: 80 | G4: 80 | H4: 80 | I4: 79 | J4: 79 | K4: 79 | L4: 79 | M4: 79 | N4: 79 | O4: 80 | P4: 82 | Q4: 82 | R4: 82 | S4: 82 | T4: 82 | U4: 82 | V4: 82 | W4: 82 | X4: 82 | Y4: 82 | Z4: 84 | AA4: 84 | AB4: 84 | AC4: 84 | AD4: 84 | AE4: 84 | AF4: 84
A5: 2 | B5: 84 | C5: 84 | D5: 84 | E5: 84 | F5: 84 | G5: 84 | H5: 84 | I5: 84 | J5: 83 | K5: 83 | L5: 83 | M5: 82 | N5: 82 | O5: 82 | P5: 82 | Q5: 82 | R5: 82 | S5: 82 | T5: 82 | U5: 82 | V5: 82 | W5: 82 | X5: 82 | Y5: 82 | Z5: 82 | AA5: 85 | AB5: 85 | AC5: 85
A6: 3 | B6: 85 | C6: 85 | D6: 85 | E6: 85 | F6: 85 | G6: 85 | H6: 85 | I6: 85 | J6: 85 | K6: 85 | L6: 85 | M6: 85 | N6: 86 | O6: 86 | P6: 86 | Q6: 86 | R6: 86 | S6: 86 | T6: 86 | U6: 86 | V6: 86 | W6: 86 | X6: 86 | Y6: 86 | Z6: 86 | AA6: 86 | AB6: 86 | AC6: 86 | AD6: 86 | AE6: 86 | AF6: 86
A7: 4 | B7: 88 | C7: 88 | D7: 88 | E7: 88 | F7: 88 | G7: 88 | H7: 88 | I7: 88 | J7: 88 | K7: 88 | L7: 88 | M7: 88 | N7: 88 | O7: 88 | P7: 89 | Q7: 89 | R7: 89 | S7: 89 | T7: 89 | U7: 88 | V7: 88 | W7: 88 | X7: 88 | Y7: 88 | Z7: 88 | AA7: 88 | AB7: 88 | AC7: 88 | AD7: 88 | AE7: 88
A8: 5 | B8: 88 | C8: 88 | D8: 88 | E8: 88 | F8: 88 | G8: 88 | H8: 88 | I8: 88 | J8: 88 | K8: 88 | L8: 89 | M8: 89 | N8: 89 | O8: 89 | P8: 89 | Q8: 89 | R8: 89 | S8: 89 | T8: 89 | U8: 89 | V8: 89 | W8: 89 | X8: 89 | Y8: 89 | Z8: 89 | AA8: 92 | AB8: 92 | AC8: 92 | AD8: 92 | AE8: 92 | AF8: 92
A9: 6 | B9: 92 | C9: 92 | D9: 92 | E9: 92 | F9: 92 | G9: 92 | H9: 92 | I9: 92 | J9: 92 | K9: 92 | L9: 92 | M9: 92 | N9: 91 | O9: 91 | P9: 91 | Q9: 91 | R9: 91 | S9: 91 | T9: 91 | U9: 91 | V9: 91 | W9: 91 | X9: 92 | Y9: 92 | Z9: 92 | AA9: 92 | AB9: 92 | AC9: 92 | AD9: 92 | AE9: 92
A10: 7 | B10: 92 | C10: 92 | D10: 92 | E10: 92 | F10: 92 | G10: 92 | H10: 92 | I10: 92 | J10: 92 | K10: 92 | L10: 92 | M10: 93 | N10: 95 | O10: 95 | P10: 95 | Q10: 95 | R10: 96 | S10: 98 | T10: 98 | U10: 98 | V10: 96 | W10: 94 | X10: 94 | Y10: 94 | Z10: 94 | AA10: 94 | AB10: 92 | AC10: 92 | AD10: 92 | AE10: 92 | AF10: 92
A11: 8 | B11: 92 | C11: 92 | D11: 92 | E11: 92 | F11: 91 | G11: 90 | H11: 90 | I11: 90 | J11: 90 | K11: 91 | L11: 92 | M11: 92 | N11: 92 | O11: 92 | P11: 92 | Q11: 92 | R11: 92 | S11: 92 | T11: 92 | U11: 92 | V11: 92 | W11: 92 | X11: 92 | Y11: 92 | Z11: 92 | AA11: 92 | AB11: 92 | AC11: 92 | AD11: 92 | AE11: 92 | AF11: 92
A12: 9 | B12: 92 | C12: 93 | D12: 93 | E12: 93 | F12: 93 | G12: 93 | H12: 93 | I12: 93 | J12: 93 | K12: 93 | L12: 93 | M12: 93 | N12: 93 | O12: 93 | P12: 93 | Q12: 93 | R12: 94 | S12: 94 | T12: 94 | U12: 94 | V12: 94 | W12: 94 | X12: 94 | Y12: 94 | Z12: 94 | AA12: 94 | AB12: 94 | AC12: 95 | AD12: 95 | AE12: 95
A13: 10 | B13: 95 | C13: 95 | D13: 95 | E13: 95 | F13: 95 | G13: 95 | H13: 94 | I13: 94 | J13: 94 | K13: 94 | L13: 94 | M13: 95 | N13: 95 | O13: 95 | P13: 95 | Q13: 95 | R13: 96 | S13: 96 | T13: 96 | U13: 96 | V13: 96 | W13: 96 | X13: 96 | Y13: 96 | Z13: 96 | AA13: 96 | AB13: 96 | AC13: 97 | AD13: 97 | AE13: 97 | AF13: 97
A14: 11 | B14: 97 | C14: 97 | D14: 97 | E14: 97 | F14: 97 | G14: 97 | H14: 97 | I14: 96 | J14: 96 | K14: 96 | L14: 96 | M14: 97 | N14: 97 | O14: 97 | P14: 99 | Q14: 99 | R14: 99 | S14: 99 | T14: 99 | U14: 99 | V14: 99 | W14: 99 | X14: 99 | Y14: 99 | Z14: 99 | AA14: 99 | AB14: 99 | AC14: 99 | AD14: 99 | AE14: 99
A15: 12 | B15: 101 | C15: 101 | D15: 101 | E15: 101 | F15: 101 | G15: 101 | H15: 101 | I15: 102 | J15: 102 | K15: 102 | L15: 102 | M15: 102 | N15: 102 | O15: 102 | P15: 102 | Q15: 102 | R15: 102 | S15: 101 | T15: 101 | U15: 101 | V15: 101 | W15: 101 | X15: 101 | Y15: 101 | Z15: 101 | AA15: 101 | AB15: 101 | AC15: 101 | AD15: 101 | AE15: 101 | AF15: 101

Sheet Bar1
A1: Artist | B1: Album | C1: Title | D1: Length | E1: Column1
A2: Bob Dylan | B2: Infidels | C2: Jokerman | D2: 0.0043865741 | E2: 0.0043865741
A3: Bob Dylan | B3: Modern Times | C3: When The Deal Goes Down | D3: 0.0035185185 | E3: 0.0035185185
A4: Bob Dylan | B4: Infidels | C4: Don't Fall Apart On Me Tonight | D4: 0.0041203704 | E4: 0.0041203704
A5: Bob Dylan | B5: Blonde On Blonde | C5: Leopard-Skin Pill-Box Hat | D5: 0.0027777778 | E5: 0.0027777778
A6: Bob Dylan | B6: Under the Red Sky | C6: 2 X 2 | D6: 0.0025 | E6: 0.0025
A7: Bob Dylan | B7: Highway 61 Revisited | C7: Just Like Tom Thumb's Blues | D7: 0.0038425926 | E7: 0.0038425926
A8: Bob Dylan | B8: Self Portrait | C8: She Belongs to Me | D8: 0.0018865741 | E8: 0.0018865741
A9: Bob Dylan | B9: New Morning | C9: New Morning | D9: 0.0027662037 | E9: 0.0027662037
A10: Bob Dylan | B10: Planet Waves | C10: Forever young | D10: 0.0034375 | E10: 0.0034375
A11: Bob Dylan | B11: 30th Anniversary Concert | C11: Emotionally Yours | D11: 0.0039699074 | E11: 0.0039699074
A12: Bob Dylan | B12: Good As I Been to You | C12: Canadee-I-O | D12: 0.0030439815 | E12: 0.0030439815
A13: Bob Dylan | B13: Down in the Groove | C13: When Did You Leave Heaven | D13: 0.0015393519 | E13: 0.0015393519
... A456: Bob Dylan | B456: Christmas in the Heart | C456: Winter Wonderland | D456: 0.0013078704 | E456: 0.0013078704

Sheet Bar2
A3: Row Labels | B3: AVG Length
A4: Tempest | B4: 0.0047523148 | D4: =B4 -> 0.0047523148 | E4: =B4 -> 0.0047523148
A5: Time Out of Mind | B5: 0.0045938552 | D5: =B5 -> 0.0045938552 | E5: =B5 -> 0.0045938552
A6: Desire | B6: 0.0043325617 | D6: =B6 -> 0.0043325617 | E6: =B6 -> 0.0043325617
A7: MTV Unplugged | B7: 0.0040467172 | D7: =B7 -> 0.0040467172 | E7: =B7 -> 0.0040467172
A8: Modern Times | B8: 0.0040352183 | D8: =B8 -> 0.0040352183 | E8: =B8 -> 0.0040352183
A9: Highway 61 Revisited | B9: 0.0039789095 | D9: =B9 -> 0.0039789095 | E9: =B9 -> 0.0039789095
A10: Street Legal | B10: 0.0038824588 | D10: =B10 -> 0.0038824588 | E10: =B10 -> 0.0038824588
A11: Infidels | B11: 0.0036603009 | D11: =B11 -> 0.0036603009 | E11: =B11 -> 0.0036603009
A12: Blonde On Blonde | B12: 0.0036284722 | D12: =B12 -> 0.0036284722 | E12: =B12 -> 0.0036284722
A13: Slow Train Coming | B13: 0.0036046811 | D13: =B13 -> 0.0036046811 | E13: =B13 -> 0.0036046811
A14: Blood On The Tracks | B14: 0.0035983796 | D14: =B14 -> 0.0035983796 | E14: =B14 -> 0.0035983796
A15: Tell Tale Signs (Disc 1) | B15: 0.0035861823 | D15: =B15 -> 0.0035861823 | E15: =B15 -> 0.0035861823
... A33: Under the Red Sky | B33: 0.0024618056 | D33: =B33 -> 0.0024618056 | E33: =B33 -> 0.0024618056
A34: Pat Garrett & Billy the Kid | B34: 0.0024525463 | D34: =B34 -> 0.0024525463
A35: Shadows in the Night | B35: 0.0024016204 | D35: =B35 -> 0.0024016204
A36: John Wesley Harding | B36: 0.0022222222 | D36: =B36 -> 0.0022222222
A37: Down in the Groove | B37: 0.0022048611 | D37: =B37 -> 0.0022048611
A38: Self Portrait | B38: 0.0021421682 | D38: =B38 -> 0.0021421682
A39: New Morning | B39: 0.0020756173 | D39: =B39 -> 0.0020756173
A40: Bob Dylan | B40: 0.0019640313 | D40: =B40 -> 0.0019640313
A41: Christmas in the Heart | B41: 0.0019537037 | D41: =B41 -> 0.0019537037
A42: Nashville Skyline | B42: 0.0018761574 | D42: =B42 -> 0.0018761574
A43: Grand Total | B43: 0.0030901252

Sheet Bar3
B3: =TRAD!E33 -> Incoming Calls
B4: 1 | C4: 2983 | D4: ='Bar3'!$C4 -> 2983
B5: 2 | C5: 3100 | D5: ='Bar3'!$C5 -> 3100
B6: 3 | C6: 4123 | D6: ='Bar3'!$C6 -> 4123
B7: 4 | C7: 4092 | D7: ='Bar3'!$C7 -> 4092
B8: 5 | C8: 4532 | D8: ='Bar3'!$C8 -> 4532
B9: 6 | C9: 3194 | D9: ='Bar3'!$C9 -> 3194
B10: 7 | C10: 2765 | D10: ='Bar3'!$C10 -> 2765
B11: 8 | C11: 2893 | D11: ='Bar3'!$C11 -> 2893
B12: 9 | C12: 4256 | D12: ='Bar3'!$C12 -> 4256
B13: 10 | C13: 3983 | D13: ='Bar3'!$C13 -> 3983
B14: 11 | C14: 4234 | D14: ='Bar3'!$C14 -> 4234
B15: 12 | C15: 6233 | D15: ='Bar3'!$C15 -> 6233

Sheet Icons
A3: =TRAD!E24 -> Month | B3: =TRAD!E25 -> Western | C3: =TRAD!E26 -> Central | D3: =TRAD!E27 -> Eastern
A4: 1 | B4: 214030 | C4: 103832 | D4: 225732 | G4: 214030 | H4: 103832 | I4: 225732
A5: 2 | B5: =B4+RANDBETWEEN(-10000,11000) -> 215816 | C5: =C4+RANDBETWEEN(-7000,5000) -> 106990 | D5: =D4+RANDBETWEEN(-17000,15000) -> 235177 | G5: 218557 | H5: 98701 | I5: 222503
A6: 3 | B6: =B5+RANDBETWEEN(-10000,11000) -> 217390 | C6: =C5+RANDBETWEEN(-7000,5000) -> 100737 | D6: =D5+RANDBETWEEN(-17000,15000) -> 222245 | G6: 219286 | H6: 96316 | I6: 227560
A7: 4 | B7: =B6+RANDBETWEEN(-10000,11000) -> 220398 | C7: =C6+RANDBETWEEN(-7000,5000) -> 101911 | D7: =D6+RANDBETWEEN(-17000,15000) -> 215063 | G7: 213417 | H7: 97994 | I7: 220100
A8: 5 | B8: =B7+RANDBETWEEN(-10000,11000) -> 213896 | C8: =C7+RANDBETWEEN(-7000,5000) -> 100136 | D8: =D7+RANDBETWEEN(-17000,15000) -> 227987 | G8: 213117 | H8: 95769 | I8: 214961
A9: 6 | B9: =B8+RANDBETWEEN(-10000,11000) -> 213102 | C9: =C8+RANDBETWEEN(-7000,5000) -> 95904 | D9: =D8+RANDBETWEEN(-17000,15000) -> 238477 | G9: 221909 | H9: 92489 | I9: 214506
A10: 7 | B10: =B9+RANDBETWEEN(-10000,11000) -> 222580 | C10: =C9+RANDBETWEEN(-7000,5000) -> 94239 | D10: =D9+RANDBETWEEN(-17000,15000) -> 251529 | G10: 212287 | H10: 90294 | I10: 222545
A11: 8 | B11: =B10+RANDBETWEEN(-10000,11000) -> 225185 | C11: =C10+RANDBETWEEN(-7000,5000) -> 89435 | D11: =D10+RANDBETWEEN(-17000,15000) -> 257692 | G11: 205930 | H11: 94085 | I11: 221376
A12: 9 | B12: =B11+RANDBETWEEN(-10000,11000) -> 229768 | C12: =C11+RANDBETWEEN(-7000,5000) -> 84163 | D12: =D11+RANDBETWEEN(-17000,15000) -> 267494 | G12: 197068 | H12: 88506 | I12: 206070
A13: 10 | B13: =B12+RANDBETWEEN(-10000,11000) -> 227505 | C13: =C12+RANDBETWEEN(-7000,5000) -> 84315 | D13: =D12+RANDBETWEEN(-17000,15000) -> 266260 | G13: 191687 | H13: 82634 | I13: 202040
A14: 11 | B14: =B13+RANDBETWEEN(-10000,11000) -> 218456 | C14: =C13+RANDBETWEEN(-7000,5000) -> 79958 | D14: =D13+RANDBETWEEN(-17000,15000) -> 275170 | G14: 182666 | H14: 81428 | I14: 216274
A15: 12 | B15: =B14+RANDBETWEEN(-10000,11000) -> 222562 | C15: =C14+RANDBETWEEN(-7000,5000) -> 81767 | D15: =D14+RANDBETWEEN(-17000,15000) -> 271047 | G15: 191655 | H15: 84186 | I15: 218408

Sheet Form1
A1: 5 | B1: 5 | X1: 5 | Y1: 5
A2: 3 | B2: John | X2: 3 | Y2: John
A3: 4 | B3: 4 | X3: 4 | Y3: 4
A4: Pierre | B4: 6 | X4: Pierre | Y4: 6
A5: 5 | B5: 5 | X5: 5 | Y5: 5
A6: Evelyne | B6: 13 | J6: Qtr-1 | K6: 2145 | X6: Evelyne | Y6: 13
A7: Zoé | B7: 21 | J7: Qtr-2 | X7: Zoé | Y7: 21
A8: 6 | B8: 6 | D8: =_xlfn.FORMULATEXT(D9) -> =ISTEXT(A1) | J8: Qtr-3 | K8: 2987 | M8: =_xlfn.FORMULATEXT(M9) -> =COUNT($K$6:$K$9)=4 | X8: 6 | Y8: 6
A9: 9 | B9: Yann | D9: =ISTEXT(A1) -> FALSE | J9: Qtr-4 | K9: 3021 | M9: =COUNT($K$6:$K$9)=4 -> FALSE | X9: 9 | Y9: Yann
A10: 8 | B10: 8 | J10: Total: | K10: =SUM(K6:K9) -> 8153 | X10: 8 | Y10: 8
W13: {=Traduire(8,2)} -> #VALUE!
A14: Name: | B14: Noel
P15: =RANDBETWEEN(1,500) -> 152 | Q15: =RANDBETWEEN(1,500) -> 58 | R15: =RANDBETWEEN(1,500) -> 347 | S15: =RANDBETWEEN(1,500) -> 124 | W15: Oct | X15: Nov | Y15: Dec
A16: Alice | B16: 7 | C16: 118 | D16: 61 | E16: 55 | F16: 85 | G16: 26 | J16: =RANDBETWEEN(1,1000) -> 794 | K16: =RANDBETWEEN(1,1000) -> 708 | L16: =RANDBETWEEN(1,1000) -> 361 | M16: =RANDBETWEEN(1,1000) -> 677 | P16: =RANDBETWEEN(1,500) -> 440 | Q16: =RANDBETWEEN(1,500) -> 456 | R16: =RANDBETWEEN(1,500) -> 441 | S16: =RANDBETWEEN(1,500) -> 306 | V16: Alice | W16: 7 | X16: 118 | Y16: 61
A17: Kathy | B17: 131 | C17: 43 | D17: 197 | E17: 82 | F17: 103 | G17: 163 | J17: =RANDBETWEEN(1,1000) -> 931 | K17: =RANDBETWEEN(1,1000) -> 681 | L17: =RANDBETWEEN(1,1000) -> 307 | M17: =RANDBETWEEN(1,1000) -> 321 | P17: =RANDBETWEEN(1,500) -> 362 | Q17: =RANDBETWEEN(1,500) -> 9 | R17: =RANDBETWEEN(1,500) -> 286 | S17: =RANDBETWEEN(1,500) -> 300 | V17: Kathy | W17: 131 | X17: 43 | Y17: 197
A18: Laurent | B18: 139 | C18: 30 | D18: 171 | E18: 122 | F18: 34 | G18: 196 | J18: =RANDBETWEEN(1,1000) -> 13 | K18: =RANDBETWEEN(1,1000) -> 533 | L18: =RANDBETWEEN(1,1000) -> 676 | M18: =RANDBETWEEN(1,1000) -> 903 | P18: =RANDBETWEEN(1,500) -> 479 | Q18: =RANDBETWEEN(1,500) -> 444 | R18: =RANDBETWEEN(1,500) -> 408 | S18: =RANDBETWEEN(1,500) -> 335 | V18: Ursula | W18: 139 | X18: 30 | Y18: 171
A19: Marie | B19: 31 | C19: 171 | D19: 185 | E19: 162 | F19: 171 | G19: 17 | J19: =RANDBETWEEN(1,1000) -> 666 | K19: =RANDBETWEEN(1,1000) -> 80 | L19: =RANDBETWEEN(1,1000) -> 574 | M19: =RANDBETWEEN(1,1000) -> 10 | P19: =RANDBETWEEN(1,500) -> 493 | Q19: =RANDBETWEEN(1,500) -> 317 | R19: =RANDBETWEEN(1,500) -> 472 | S19: =RANDBETWEEN(1,500) -> 248 | V19: Vincent | W19: 31 | X19: 171 | Y19: 185
A20: Noel | B20: 78 | C20: 126 | D20: 190 | E20: 78 | F20: 123 | G20: 2 | J20: =RANDBETWEEN(1,1000) -> 822 | K20: =RANDBETWEEN(1,1000) -> 300 | L20: =RANDBETWEEN(1,1000) -> 376 | M20: =RANDBETWEEN(1,1000) -> 340 | P20: =RANDBETWEEN(1,500) -> 309 | Q20: =RANDBETWEEN(1,500) -> 300 | R20: =RANDBETWEEN(1,500) -> 253 | S20: =RANDBETWEEN(1,500) -> 242 | V20: Walter | W20: 78 | X20: 126 | Y20: 190
A21: Oliver | B21: 157 | C21: 98 | D21: 100 | E21: 75 | F21: 137 | G21: 10 | J21: =RANDBETWEEN(1,1000) -> 59 | K21: =RANDBETWEEN(1,1000) -> 638 | L21: =RANDBETWEEN(1,1000) -> 300 | M21: =RANDBETWEEN(1,1000) -> 807 | P21: =RANDBETWEEN(1,500) -> 113 | Q21: =RANDBETWEEN(1,500) -> 56 | R21: =RANDBETWEEN(1,500) -> 13 | S21: =RANDBETWEEN(1,500) -> 440 | V21: Bertrand | W21: 157 | X21: 98 | Y21: 100
A22: Patrick | B22: 120 | C22: 144 | D22: 106 | E22: 39 | F22: 39 | G22: 119 | J22: =RANDBETWEEN(1,1000) -> 596 | K22: =RANDBETWEEN(1,1000) -> 54 | L22: =RANDBETWEEN(1,1000) -> 879 | M22: =RANDBETWEEN(1,1000) -> 759 | P22: =RANDBETWEEN(1,500) -> 124 | Q22: =RANDBETWEEN(1,500) -> 382 | R22: =RANDBETWEEN(1,500) -> 274 | S22: =RANDBETWEEN(1,500) -> 141 | V22: Yolanda | W22: 120 | X22: 144 | Y22: 106
A23: Cléa | B23: 156 | C23: 200 | D23: 58 | E23: 74 | F23: 37 | G23: 76 | J23: =RANDBETWEEN(1,1000) -> 822 | K23: =RANDBETWEEN(1,1000) -> 613 | L23: =RANDBETWEEN(1,1000) -> 31 | M23: =RANDBETWEEN(1,1000) -> 206 | P23: =RANDBETWEEN(1,500) -> 267 | Q23: =RANDBETWEEN(1,500) -> 396 | R23: =RANDBETWEEN(1,500) -> 267 | S23: =RANDBETWEEN(1,500) -> 356 | V23: Jean | W23: 156 | X23: 200 | Y23: 58
A24: Raoul | B24: 58 | C24: 147 | D24: 160 | E24: 182 | F24: 11 | G24: 79 | J24: =RANDBETWEEN(1,1000) -> 307 | K24: =RANDBETWEEN(1,1000) -> 262 | L24: =RANDBETWEEN(1,1000) -> 183 | M24: =RANDBETWEEN(1,1000) -> 934 | P24: =RANDBETWEEN(1,500) -> 456 | Q24: =RANDBETWEEN(1,500) -> 376 | R24: =RANDBETWEEN(1,500) -> 406 | S24: =RANDBETWEEN(1,500) -> 103
A25: Sheila | B25: 79 | C25: 183 | D25: 5 | E25: 161 | F25: 104 | G25: 23 | J25: =RANDBETWEEN(1,1000) -> 932 | K25: =RANDBETWEEN(1,1000) -> 155 | L25: =RANDBETWEEN(1,1000) -> 578 | M25: =RANDBETWEEN(1,1000) -> 618 | P25: =RANDBETWEEN(1,500) -> 476 | Q25: =RANDBETWEEN(1,500) -> 81 | R25: =RANDBETWEEN(1,500) -> 496 | S25: =RANDBETWEEN(1,500) -> 374
A26: Tom | B26: 91 | C26: 54 | D26: 100 | E26: 174 | F26: 198 | G26: 78 | J26: =RANDBETWEEN(1,1000) -> 133 | K26: =RANDBETWEEN(1,1000) -> 928 | L26: =RANDBETWEEN(1,1000) -> 339 | M26: =RANDBETWEEN(1,1000) -> 460 | P26: =RANDBETWEEN(1,500) -> 332 | Q26: =RANDBETWEEN(1,500) -> 114 | R26: =RANDBETWEEN(1,500) -> 157 | S26: =RANDBETWEEN(1,500) -> 326
A27: Ursula | B27: 53 | C27: 140 | D27: 188 | E27: 58 | F27: 54 | G27: 36 | J27: =RANDBETWEEN(1,1000) -> 13 | K27: =RANDBETWEEN(1,1000) -> 324 | L27: =RANDBETWEEN(1,1000) -> 375 | M27: =RANDBETWEEN(1,1000) -> 349 | P27: =RANDBETWEEN(1,500) -> 381 | Q27: =RANDBETWEEN(1,500) -> 290 | R27: =RANDBETWEEN(1,500) -> 99 | S27: =RANDBETWEEN(1,500) -> 50
A28: Vincent | B28: 121 | C28: 13 | D28: 2 | E28: 139 | F28: 148 | G28: 101 | J28: =RANDBETWEEN(1,1000) -> 213 | K28: =RANDBETWEEN(1,1000) -> 474 | L28: =RANDBETWEEN(1,1000) -> 546 | M28: =RANDBETWEEN(1,1000) -> 369 | P28: =RANDBETWEEN(1,500) -> 331 | Q28: =RANDBETWEEN(1,500) -> 115 | R28: =RANDBETWEEN(1,500) -> 28 | S28: =RANDBETWEEN(1,500) -> 55 | W28: =_xlfn.FORMULATEXT(W29) -> =OR($V16="Bertrand";W$15="Nov")
A29: Walter | B29: 132 | C29: 65 | D29: 123 | E29: 129 | F29: 174 | G29: 90 | J29: =RANDBETWEEN(1,1000) -> 293 | K29: =RANDBETWEEN(1,1000) -> 149 | L29: =RANDBETWEEN(1,1000) -> 338 | M29: =RANDBETWEEN(1,1000) -> 644 | P29: =RANDBETWEEN(1,500) -> 312 | Q29: =RANDBETWEEN(1,500) -> 307 | R29: =RANDBETWEEN(1,500) -> 336 | S29: =RANDBETWEEN(1,500) -> 480 | W29: =OR($V16="Bertrand",W$15="Nov") -> FALSE
A30: Bertrand | B30: 162 | C30: 127 | D30: 86 | E30: 51 | F30: 164 | G30: 35 | J30: =RANDBETWEEN(1,1000) -> 288 | K30: =RANDBETWEEN(1,1000) -> 621 | L30: =RANDBETWEEN(1,1000) -> 899 | M30: =RANDBETWEEN(1,1000) -> 974 | P30: =RANDBETWEEN(1,500) -> 413 | Q30: =RANDBETWEEN(1,500) -> 313 | R30: =RANDBETWEEN(1,500) -> 72 | S30: =RANDBETWEEN(1,500) -> 81
A31: Yolanda | B31: 60 | C31: 116 | D31: 107 | E31: 117 | F31: 189 | G31: 200 | J31: =RANDBETWEEN(1,1000) -> 583 | K31: =RANDBETWEEN(1,1000) -> 422 | L31: =RANDBETWEEN(1,1000) -> 400 | M31: =RANDBETWEEN(1,1000) -> 750 | P31: =RANDBETWEEN(1,500) -> 489 | Q31: =RANDBETWEEN(1,500) -> 241 | R31: =RANDBETWEEN(1,500) -> 316 | S31: =RANDBETWEEN(1,500) -> 246
A32: Jean | B32: 103 | C32: 142 | D32: 103 | E32: 165 | F32: 89 | G32: 37 | J32: =RANDBETWEEN(1,1000) -> 69 | K32: =RANDBETWEEN(1,1000) -> 640 | L32: =RANDBETWEEN(1,1000) -> 387 | M32: =RANDBETWEEN(1,1000) -> 700 | P32: =RANDBETWEEN(1,500) -> 101 | Q32: =RANDBETWEEN(1,500) -> 120 | R32: =RANDBETWEEN(1,500) -> 278 | S32: =RANDBETWEEN(1,500) -> 99
J33: =RANDBETWEEN(1,1000) -> 506 | K33: =RANDBETWEEN(1,1000) -> 985 | L33: =RANDBETWEEN(1,1000) -> 91 | M33: =RANDBETWEEN(1,1000) -> 872 | P33: =RANDBETWEEN(1,500) -> 157 | Q33: =RANDBETWEEN(1,500) -> 105 | R33: =RANDBETWEEN(1,500) -> 284 | S33: =RANDBETWEEN(1,500) -> 332
P34: =RANDBETWEEN(1,500) -> 330 | Q34: =RANDBETWEEN(1,500) -> 13 | R34: =RANDBETWEEN(1,500) -> 118 | S34: =RANDBETWEEN(1,500) -> 310
P35: =RANDBETWEEN(1,500) -> 134 | Q35: =RANDBETWEEN(1,500) -> 295 | R35: =RANDBETWEEN(1,500) -> 474 | S35: =RANDBETWEEN(1,500) -> 373
C36: =_xlfn.FORMULATEXT(C37) -> =$A16=$B$14 | K36: =_xlfn.FORMULATEXT(K37) -> =MOD(ROW();2)=0
C37: =$A16=$B$14 -> FALSE | K37: =MOD(ROW(),2)=0 -> FALSE
Q38: =_xlfn.FORMULATEXT(Q39) -> =MOD(INT((ROW()-1)/4)+1;2)=1
Q39: =MOD(INT((ROW()-1)/4)+1,2)=1 -> FALSE

Sheet Form2
A2: 11 | B2: 43 | C2: 38 | D2: =TRAD!E19 -> <-- Value to highlight | L2: =TODAY() -> 46175 | M2: =L2 -> 46175 | Q2: =INT(RAND()*1000) -> 831 | R2: =INT(RAND()*1000) -> 539 | S2: =INT(RAND()*1000) -> 123 | T2: =INT(RAND()*1000) -> 9 | U2: =INT(RAND()*1000) -> 259 | V2: =INT(RAND()*1000) -> 184 | W2: =INT(RAND()*1000) -> 226 | X2: =INT(RAND()*1000) -> 509
A3: 28 | B3: 6 | L3: =L2+1 -> 46176 | M3: =L3 -> 46176 | Q3: =INT(RAND()*1000) -> 1 | R3: =INT(RAND()*1000) -> 297 | S3: =INT(RAND()*1000) -> 168 | T3: =INT(RAND()*1000) -> 580 | U3: =INT(RAND()*1000) -> 823 | V3: =INT(RAND()*1000) -> 730 | W3: =INT(RAND()*1000) -> 97 | X3: =INT(RAND()*1000) -> 539
A4: 25 | B4: 48 | L4: =L3+1 -> 46177 | M4: =L4 -> 46177 | Q4: =INT(RAND()*1000) -> 571 | R4: =INT(RAND()*1000) -> 180 | S4: =INT(RAND()*1000) -> 678 | T4: =INT(RAND()*1000) -> 63 | U4: =INT(RAND()*1000) -> 928 | V4: =INT(RAND()*1000) -> 855 | W4: =INT(RAND()*1000) -> 412 | X4: =INT(RAND()*1000) -> 702
A5: 2 | B5: 38 | L5: =L4+1 -> 46178 | M5: =L5 -> 46178 | Q5: =INT(RAND()*1000) -> 759 | R5: =INT(RAND()*1000) -> 63 | S5: =INT(RAND()*1000) -> 638 | T5: =INT(RAND()*1000) -> 354 | U5: =INT(RAND()*1000) -> 182 | V5: =INT(RAND()*1000) -> 685 | W5: =INT(RAND()*1000) -> 910 | X5: =INT(RAND()*1000) -> 135
A6: 7 | B6: 12 | L6: =L5+1 -> 46179 | M6: =L6 -> 46179 | Q6: =INT(RAND()*1000) -> 929 | R6: =INT(RAND()*1000) -> 151 | S6: =INT(RAND()*1000) -> 662 | T6: =INT(RAND()*1000) -> 761 | U6: =INT(RAND()*1000) -> 35 | V6: =INT(RAND()*1000) -> 663 | W6: =INT(RAND()*1000) -> 308 | X6: =INT(RAND()*1000) -> 320
A7: 43 | B7: 38 | L7: =L6+1 -> 46180 | M7: =L7 -> 46180 | Q7: =INT(RAND()*1000) -> 932 | R7: =INT(RAND()*1000) -> 324 | S7: =INT(RAND()*1000) -> 15 | T7: =INT(RAND()*1000) -> 503 | U7: =INT(RAND()*1000) -> 787 | V7: =INT(RAND()*1000) -> 202 | W7: =INT(RAND()*1000) -> 897 | X7: =INT(RAND()*1000) -> 501
A8: 17 | B8: 18 | L8: =L7+1 -> 46181 | M8: =L8 -> 46181 | Q8: =INT(RAND()*1000) -> 609 | R8: =INT(RAND()*1000) -> 766 | S8: =INT(RAND()*1000) -> 535 | T8: =INT(RAND()*1000) -> 397 | U8: =INT(RAND()*1000) -> 845 | V8: =INT(RAND()*1000) -> 474 | W8: =INT(RAND()*1000) -> 808 | X8: =INT(RAND()*1000) -> 17
A9: 13 | B9: 40 | L9: =L8+1 -> 46182 | M9: =L9 -> 46182 | Q9: =INT(RAND()*1000) -> 282 | R9: =INT(RAND()*1000) -> 785 | S9: =INT(RAND()*1000) -> 207 | T9: =INT(RAND()*1000) -> 190 | U9: =INT(RAND()*1000) -> 104 | V9: =INT(RAND()*1000) -> 145 | W9: =INT(RAND()*1000) -> 326 | X9: =INT(RAND()*1000) -> 178
A10: 4 | B10: 14 | L10: =L9+1 -> 46183 | M10: =L10 -> 46183 | Q10: =INT(RAND()*1000) -> 289 | R10: =INT(RAND()*1000) -> 373 | S10: =INT(RAND()*1000) -> 748 | T10: =INT(RAND()*1000) -> 77 | U10: =INT(RAND()*1000) -> 768 | V10: =INT(RAND()*1000) -> 255 | W10: =INT(RAND()*1000) -> 226 | X10: =INT(RAND()*1000) -> 252
A11: 47 | B11: 47 | L11: =L10+1 -> 46184 | M11: =L11 -> 46184 | Q11: =INT(RAND()*1000) -> 698 | R11: =INT(RAND()*1000) -> 509 | S11: =INT(RAND()*1000) -> 320 | T11: =INT(RAND()*1000) -> 381 | U11: =INT(RAND()*1000) -> 520 | V11: =INT(RAND()*1000) -> 27 | W11: =INT(RAND()*1000) -> 860 | X11: =INT(RAND()*1000) -> 656
A12: 20 | B12: 39 | L12: =L11+1 -> 46185 | M12: =L12 -> 46185 | Q12: =INT(RAND()*1000) -> 0 | R12: =INT(RAND()*1000) -> 628 | S12: =INT(RAND()*1000) -> 449 | T12: =INT(RAND()*1000) -> 772 | U12: =INT(RAND()*1000) -> 991 | V12: =INT(RAND()*1000) -> 83 | W12: =INT(RAND()*1000) -> 990 | X12: =INT(RAND()*1000) -> 143
A13: 18 | B13: 38 | L13: =L12+1 -> 46186 | M13: =L13 -> 46186 | Q13: =INT(RAND()*1000) -> 881 | R13: =INT(RAND()*1000) -> 631 | S13: =INT(RAND()*1000) -> 7 | T13: =INT(RAND()*1000) -> 518 | U13: =INT(RAND()*1000) -> 9 | V13: =INT(RAND()*1000) -> 24 | W13: =INT(RAND()*1000) -> 713 | X13: =INT(RAND()*1000) -> 697
A14: 10 | B14: 32 | L14: =L13+1 -> 46187 | M14: =L14 -> 46187 | Q14: =INT(RAND()*1000) -> 314 | R14: =INT(RAND()*1000) -> 859 | S14: =INT(RAND()*1000) -> 530 | T14: =INT(RAND()*1000) -> 203 | U14: =INT(RAND()*1000) -> 237 | V14: =INT(RAND()*1000) -> 551 | W14: =INT(RAND()*1000) -> 262 | X14: =INT(RAND()*1000) -> 294
... A23: 21 | B23: 19 | L23: =L22+1 -> 46196 | M23: =L23 -> 46196 | Q23: =INT(RAND()*1000) -> 415 | R23: =INT(RAND()*1000) -> 687 | S23: =INT(RAND()*1000) -> 136 | T23: =INT(RAND()*1000) -> 578 | U23: =INT(RAND()*1000) -> 939 | V23: =INT(RAND()*1000) -> 999 | W23: =INT(RAND()*1000) -> 872 | X23: =INT(RAND()*1000) -> 72
A24: 15 | B24: 27 | L24: =L23+1 -> 46197 | M24: =L24 -> 46197
A25: 12 | B25: 41 | L25: =L24+1 -> 46198 | M25: =L25 -> 46198
A26: 8 | B26: 1 | L26: =L25+1 -> 46199 | M26: =L26 -> 46199
A27: 3 | B27: 21 | L27: =L26+1 -> 46200 | M27: =L27 -> 46200
A28: 34 | B28: 19 | L28: =L27+1 -> 46201 | M28: =L28 -> 46201
A29: 32 | B29: 42 | L29: =L28+1 -> 46202 | M29: =L29 -> 46202
A30: 20 | B30: 4 | L30: =L29+1 -> 46203 | M30: =L30 -> 46203
A31: 30 | B31: 11
A32: 20 | B32: 24
A33: 50 | B33: 9
A34: 10 | B34: 8
A35: 26 | B35: 43
A36: 5 | B36: 1
A37: 4 | B37: 16
A38: 46 | B38: 32
A39: 14 | B39: 44
A40: 39 | B40: 38
A41: 32 | B41: 47
A42: 24 | B42: 15
... A85: 36 | B85: 36

Sheet Basic Data validation
A5: 44666 | C5: =TRAD!E40 -> Only dates between 2020 and 2025
A11: -15
A12: 0
A13: 5
C14: =TRAD!E56 -> Only whole numbers over -100
A20: 0.35069444 | C20: =TRAD!$E$58 -> Hours between 8 am and 7 pm
A21: 0.65625
A23: 0.13194444 | B23: Information
A25: 0.12847222 | B25: =TRAD!$E$60 -> Warning
B27: STOP

Sheet Text
A1: Excel | J1: =TRAD!$E$41 -> Must start with "xl" and be 6 characters long at least
C2: =TRAD!E36 -> Accept only text entries | H2: xl1234
H3: xl123456 | J3: =_xlfn.FORMULATEXT(J4) -> =AND(LEFT(H2;2)="xl";LEN(H2)>=6)
A4: zguz | C4: =_xlfn.FORMULATEXT(C5) -> =ISTEXT(A4) | J4: =AND(LEFT(H2,2)="xl",LEN(H2)>=6) -> TRUE
A5: jnij | C5: =ISTEXT(A4) -> TRUE
A6: 54…

Sheet LargerThanPrevious
A1: 100
A2: 132 | C2: =TRAD!E37 -> Accept value only if it is larger than the previous cell
A3: 155
C5: =A2>A1

Sheet Dropdown from list
A5: GE
A9: GE
A17: FR
A18: BE | C18: VD;GE;VS;FR;NE;BE;ZH

Sheet Dropdown from range
I1: =_xlfn.FORMULATEXT(I2) -> =SORT(H2:H8) | K1: =TRAD!$E$62 -> Defined name
A2: FR | H2: VD | I2: {=_xlfn._xlws.SORT(H2:H8)} -> BE | K2: {=_xlfn._xlws.SORT($H$2:$H$8)} -> BE
A3: NE | H3: VS | I3: FR | K3: FR
A4: VD | H4: ZH | I4: GE | K4: GE | O4: GE
H5: NE | I5: NE | K5: NE | O5: FR
H6: BE | I6: VD | K6: VD | O6: GE
H7: GE | I7: VS | K7: VS | O7: BE
H8: FR | I8: ZH | K8: ZH
A10: =$I$2:$I$8 | O10: =Cantons#

Sheet NonDuplicates
A1: 1 | B1: 32
A2: 2 | B2: 33 | E2: =TRAD!E44 -> Accepts only non-duplicated data
A3: 3 | B3: 34
A4: 4 | B4: 35 | E4: =NB.SI($A$1:$C$20;A1)=1
A5: 5
A6: 6
A7: 7
A8: 8
A9: 9
A10: 10
A11: 11
A12: 12
A13: 13
A14: 14
A15: 15
A16: 16
... A20: 20

Sheet BeginWithA
A1: Alpha
A2: apple | C2: =TRAD!E46 -> Accept entry only if it begins with A
A3: Amos
C4: =GAUCHE(A1)="a"
A5: Abc
A7: Aaaaaa

Sheet Pattern
A1: Alpha
A2: apple | C2: =TRAD!E48 -> Accept entry only if it begins with A and contains five characters
A3: Aaron
C5: =NB.SI(A1;"A????")=1

Sheet MondayOnly
A1: 44704
A2: 44382 | C2: =TRAD!E50 -> Accept date entry only if it is a Monday.
A4: =DATE(2023,9,18) -> 45187
C5: =JOURSEM(A1)=2

Sheet StayWithinBudget
A1: Meat: | B1: 120
A2: Vegetables: | B2: 25 | D2: =TRAD!E52 -> Accept a value only if it doesn't go over the budget.
A3: Fruit: | B3: 50
A4: Snacks: | B4: 40 | D4: =SOMME($B$1:$B$6)<=$B$12
A5: Alcohol: | B5: 200
A6: Soft Drinks: | B6: 50
A12: Budget: | B12: 500
A13: Total: | B13: =SUM(B1:B6) -> 485

Sheet Dependent (INDIRECT)
A1: BIENNE | B1: LAUSANNE | C1: GENEVE
A2: Beaumont | B2: Centre | C2: Acacias | E2: GENEVE | F2: Champs-de-Boujean
A3: Boujean | B3: Florimont | C3: Champel
A4: Centre-Ville | B4: Maupas/Valency | C4: Cologny | F4: =TRAD!E54 -> List values depend on the parent list
A5: Champs-de-Boujean | B5: Montchoisi | C5: Eaux-Vives | F5: =_xlfn.FORMULATEXT(F6) -> =INDIRECT($E$2)
A6: Gurzelen | B6: Montoie/Bourdonette | C6: Grand-Saconnex | F6: {=INDIRECT($E$2)} -> Acacias
A7: Mâche | B7: Montriond/Cour | C7: Grottes Saint-Gervais | F7: Champel
A8: Madretsch | B8: Sébeillon/Malley | C8: Nations | F8: Cologny
A9: Quartiers du Lac | B9: Vieille Ville | C9: Pâquis | F9: Eaux-Vives
A10: Vieille Ville | B10: Ouchy | C10: Petit-Saconnex | F10: Grand-Saconnex
A11: Vigneules | C11: Plainpalais | F11: Grottes Saint-Gervais
C12: Saint-Jean | F12: Nations
C13: Servette | F13: Pâquis
C14: Vielle-Ville | F14: Petit-Saconnex
F15: Plainpalais
F16: Saint-Jean
F17: Servette
F18: Vielle-Ville
