Workbook
Name CH: Variables!$H$3
Name D: Variables!$H$6
Name FR: Variables!$H$5
Name GB: Variables!$H$8
Name I3liste: #REF!
Name IT: Variables!$H$7
Name liste_cantons: Variables!$B$11:$B$15
Name tax10pc: Variables!$B$4
Name tax12pc: Variables!$B$6
Name TVACH: Variables!$H$3
Name US: Variables!$H$4

Sheet 1. Lignes-cols
A1: =Variables!$A$1 -> #VALUE! | K1: Ludovic Moreau moreau@artofnet.ch
D3: medal_code | E3: medal_date | F3: name | G3: NOCID | H3: compound key | I3: DisciplineID | J3: Name in Athletes table | K3: AthleteID
D4: 1 | E4: mardi, 30 juillet 2024 | F4: Daniel WIFFEN | G4: 99 | H4: daniel wiffen - 99 | I4: 261 | J4: WIFFEN Daniel | K4: 1539969
D5: 1 | E5: lundi, 29 juillet 2024 | F5: David POPOVICI | G5: 171 | H5: david popovici - 171 | I5: 259 | J5: POPOVICI David | K5: 1543549
D6: 1 | E6: samedi, 10 août 2024 | F6: Arian SALIMI | G6: 98 | H6: arian salimi - 98 | I6: 283 | J6: SALIMI Arian | K6: 1536045
D7: 1 | E7: samedi, 3 août 2024 | F7: Julien ALFRED | G7: 122 | H7: julien alfred - 122 | I7: 45 | J7: ALFRED Julien | K7: 1537325
D8: 1 | E8: mercredi, 31 juillet 2024 | F8: Lasha BEKAURI | G8: 80 | H8: lasha bekauri - 80 | I8: 179 | J8: BEKAURI Lasha | K8: 1548817
D9: 1 | E9: mercredi, 31 juillet 2024 | F9: Cassandre BEAUGRAND | G9: 72 | H9: cassandre beaugrand - 72 | I9: 295 | J9: BEAUGRAND Cassandre | K9: 1543963
D10: 1 | E10: dimanche, 11 août 2024 | F10: Akhmed TAZHUDINOV | G10: 31 | H10: akhmed tazhudinov - 31 | I10: 328 | J10: TAZHUDINOV Akhmed | K10: 1540305
D11: 1 | E11: vendredi, 9 août 2024 | F11: Imane KHELIF | G11: 5 | H11: imane khelif - 5 | I11: 92 | J11: KHELIF Imane | K11: 1540353
D12: 1 | E12: dimanche, 4 août 2024 | F12: Kaylia NEMOUR | G12: 5 | H12: kaylia nemour - 5 | I12: 17 | J12: NEMOUR Kaylia | K12: 1545688
D13: 1 | E13: lundi, 5 août 2024 | F13: Alice D'AMATO | G13: 104 | H13: alice d'amato - 104 | I13: 18 | J13: D'AMATO Alice | K13: 1551061
D14: 1 | E14: vendredi, 9 août 2024 | F14: Toby ROBERTS | G14: 77 | H14: toby roberts - 77 | I14: 236 | J14: ROBERTS Toby | K14: 1544218
D15: 1 | E15: mercredi, 7 août 2024 | F15: Mohammadhadi SARAVI | G15: 98 | H15: mohammadhadi saravi - 98 | I15: 316 | J15: SARAVI Mohammadhadi | K15: 1544897
... D30: 1 | E30: mercredi, 7 août 2024 | F30: Aleksandra MIROSLAW | G30: 164 | H30: aleksandra miroslaw - 164 | I30: 235 | J30: MIROSLAW Aleksandra | K30: 1563327
E31: mercredi, 7 août 2024 | F31: Oleksandr KHYZHNIAK | G31: 212 | H31: oleksandr khyzhniak - 212 | I31: 85 | J31: KHYZHNIAK Oleksandr | K31: 1564362
D32: 1 | E32: vendredi, 9 août 2024 | F32: Valentin BONTUS | G32: 14 | H32: valentin bontus - 14 | I32: 206 | J32: BONTUS Valentin | K32: 1566437
D33: 1 | E33: dimanche, 28 juillet 2024 | F33: Diyora KELDIYOROVA | G33: 216 | H33: diyora keldiyorova - 216 | I33: 169 | J33: KELDIYOROVA Diyora | K33: 1566997
D34: 1 | E34: lundi, 5 août 2024 | F34: Kauli VAAST | G34: 72 | H34: kauli vaast - 72 | I34: 238 | J34: VAAST Kauli | K34: 1567361
D35: 1 | E35: lundi, 5 août 2024 | F35: Armand DUPLANTIS | G35: 194 | H35: armand duplantis - 194 | I35: 34 | J35: DUPLANTIS Armand | K35: 1569203
D36: 1 | E36: mardi, 6 août 2024 | F36: Mijain LOPEZ NUNEZ | G36: 54 | H36: mijain lopez nunez - 54 | I36: 317 | J36: LOPEZ NUNEZ Mijain | K36: 1571506
D37: 1 | E37: dimanche, 4 août 2024 | F37: Yaroslava MAHUCHIKH | G37: 212 | H37: yaroslava mahuchikh - 212 | I37: 56 | J37: MAHUCHIKH Yaroslava | K37: 1571559
D38: 1 | E38: vendredi, 9 août 2024 | F38: Viviana MARTON | G38: 93 | H38: viviana marton - 93 | I38: 286 | J38: MARTON Viviana | K38: 1572318
D39: 1 | E39: mercredi, 31 juillet 2024 | F39: Sarah SJOESTROEM | G39: 194 | H39: sarah sjoestroem - 194 | I39: 241 | J39: SJOESTROEM Sarah | K39: 1572557
D40: 1 | E40: dimanche, 4 août 2024 | F40: Sarah SJOESTROEM | G40: 194 | H40: sarah sjoestroem - 194 | I40: 240 | J40: SJOESTROEM Sarah | K40: 1572557
D41: 1 | E41: samedi, 3 août 2024 | F41: Markus ROOTH | G41: 151 | H41: markus rooth - 151 | I41: 41 | J41: ROOTH Markus | K41: 1878353
D42: 1 | E42: jeudi, 8 août 2024 | F42: Arshad NADEEM | G42: 156 | H42: arshad nadeem - 156 | I42: 40 | J42: NADEEM Arshad | K42: 1878563
D43: 1 | E43: samedi, 10 août 2024 | F43: Solfrid Eila Amena KOANDA | G43: 151 | H43: solfrid eila amena koanda - 151 | I43: 305 | J43: KOANDA Solfrid Eila Amena | K43: 1878625
... D732: 2 | E732: mercredi, 7 août 2024 | F732: Kenneth ROOKS | G732: 215 | H732: kenneth rooks - 215 | I732: 30 | J732: ROOKS Kenneth | K732: 1965896

Sheet 2. Cellules
A1: =Variables!$A$1 -> #VALUE!
D3: medal_code | E3: medal_date | F3: name | G3: NOCID | H3: compound key | I3: DisciplineID | J3: AthleteID
D4: 1 | E4: mardi, 30 juillet 2024 | F4: Daniel WIFFEN | G4: 99 | H4: daniel wiffen - 99 | I4: 261 | J4: 1539969
D5: 1 | E5: lundi, 29 juillet 2024 | F5: David POPOVICI | G5: 171 | H5: david popovici - 171 | I5: 259 | J5: 1543549
D6: 1 | E6: samedi, 10 août 2024 | F6: Arian SALIMI | G6: 98 | H6: arian salimi - 98 | I6: 283 | J6: 1536045
D7: 1 | E7: samedi, 3 août 2024 | F7: Julien ALFRED | G7: 122 | H7: julien alfred - 122 | I7: 45 | J7: 1537325
D8: 1 | E8: mercredi, 31 juillet 2024 | F8: Lasha BEKAURI | G8: 80 | H8: lasha bekauri - 80 | I8: 179 | J8: 1548817
D9: 1 | E9: mercredi, 31 juillet 2024 | F9: Cassandre BEAUGRAND | G9: 72 | H9: cassandre beaugrand - 72 | I9: 295 | J9: 1543963
D10: 1 | E10: dimanche, 11 août 2024 | F10: Akhmed TAZHUDINOV | G10: 31 | H10: akhmed tazhudinov - 31 | I10: 328 | J10: 1540305
D11: 1 | E11: vendredi, 9 août 2024 | F11: Imane KHELIF | G11: 5 | H11: imane khelif - 5 | I11: 92 | J11: 1540353
D12: 1 | E12: dimanche, 4 août 2024 | F12: Kaylia NEMOUR | G12: 5 | H12: kaylia nemour - 5 | I12: 17
D13: 1 | E13: lundi, 5 août 2024 | F13: Alice D'AMATO | G13: 104 | H13: alice d'amato - 104 | I13: 18 | J13: 1551061
D14: 1 | E14: vendredi, 9 août 2024 | F14: Toby ROBERTS | G14: 77 | H14: toby roberts - 77 | I14: 236 | J14: 1544218
D15: 1 | E15: mercredi, 7 août 2024 | F15: Mohammadhadi SARAVI | G15: 98 | H15: mohammadhadi saravi - 98 | I15: 316 | J15: 1544897
D16: 1 | E16: jeudi, 8 août 2024 | F16: Saeid ESMAEILI LEIVESI | G16: 98 | H16: saeid esmaeili leivesi - 98 | I16: 313 | J16: 1544928
D17: 1 | E17: samedi, 10 août 2024 | F17: Lasha TALAKHADZE | G17: 80 | H17: lasha talakhadze - 80 | I17: 311 | J17: 1551443
D18: 1 | E18: samedi, 10 août 2024 | F18: Geno PETRIASHVILI | G18: 80 | H18: geno petriashvili - 80 | I18: 329
D19: 1 | E19: mardi, 6 août 2024 | F19: Kellie HARRINGTON | G19: 99 | H19: kellie harrington - 99 | I19: 91 | J19: 1555098
D20: 1 | E20: mercredi, 7 août 2024 | F20: Soufiane EL BAKKALI | G20: 128 | H20: soufiane el bakkali - 128 | I20: 30 | J20: 1555372
D21: 1 | E21: mercredi, 7 août 2024 | F21: Erislandy ALVAREZ BORGES | G21: 54 | H21: erislandy alvarez borges - 54 | I21: 83 | J21: 1555537
D22: 1 | E22: jeudi, 8 août 2024 | F22: Hasanboy DUSMATOV | G22: 216 | H22: hasanboy dusmatov - 216 | I22: 81 | J22: 1556045
D23: 1 | E23: samedi, 10 août 2024 | F23: Abdumalik KHALOKOV | G23: 216 | H23: abdumalik khalokov - 216 | I23: 82 | J23: 1556049
D24: 1 | E24: vendredi, 9 août 2024 | F24: Asadkhuja MUYDINKHUJAEV | G24: 216 | H24: asadkhuja muydinkhujaev - 216 | I24: 84 | J24: 1556797
D25: 1 | E25: vendredi, 9 août 2024 | F25: Lazizbek MULLOJONOV | G25: 216 | H25: lazizbek mullojonov - 216 | I25: 86 | J25: 1556860
D26: 1 | E26: samedi, 10 août 2024 | F26: Bakhodir JALOLOV | G26: 216 | H26: bakhodir jalolov - 216 | I26: 87 | J26: 1556869
D27: 1 | E27: vendredi, 9 août 2024 | F27: Magomed Eldarovitch RAMAZANOV | G27: 33 | H27: magomed eldarovitch ramazanov - 33 | I27: 327 | J27: 1556873
D28: 1 | E28: jeudi, 8 août 2024 | F28: Semen Sergeevich NOVIKOV | G28: 33 | H28: semen sergeevich novikov - 33 | I28: 315 | J28: 1559471
D29: 1 | E29: samedi, 10 août 2024 | F29: Razambek Salambekovitch JAMALOV | G29: 216 | H29: razambek salambekovitch jamalov - 216 | I29: 326 | J29: 1562164
D30: 1 | E30: mercredi, 7 août 2024 | F30: Aleksandra MIROSLAW | G30: 164 | H30: aleksandra miroslaw - 164 | I30: 235 | J30: 1563327
D31: 1 | E31: mercredi, 7 août 2024 | F31: Oleksandr KHYZHNIAK | G31: 212 | H31: oleksandr khyzhniak - 212 | I31: 85
D32: 1 | E32: vendredi, 9 août 2024 | F32: Valentin BONTUS | G32: 14 | H32: valentin bontus - 14 | I32: 206 | J32: 1566437
D33: 1 | E33: dimanche, 28 juillet 2024 | F33: Diyora KELDIYOROVA | G33: 216 | H33: diyora keldiyorova - 216 | I33: 169 | J33: 1566997
D34: 1 | E34: lundi, 5 août 2024 | F34: Kauli VAAST | G34: 72 | H34: kauli vaast - 72 | I34: 238 | J34: 1567361
D35: 1 | E35: lundi, 5 août 2024 | F35: Armand DUPLANTIS | G35: 194 | H35: armand duplantis - 194 | I35: 34 | J35: 1569203
D36: 1 | E36: mardi, 6 août 2024 | F36: Mijain LOPEZ NUNEZ | G36: 54 | H36: mijain lopez nunez - 54 | I36: 317 | J36: 1571506
D37: 1 | E37: dimanche, 4 août 2024 | F37: Yaroslava MAHUCHIKH | G37: 212 | H37: yaroslava mahuchikh - 212 | I37: 56 | J37: 1571559
D38: 1 | E38: vendredi, 9 août 2024 | F38: Viviana MARTON | G38: 93 | H38: viviana marton - 93 | I38: 286 | J38: 1572318
D39: 1 | E39: mercredi, 31 juillet 2024 | F39: Sarah SJOESTROEM | G39: 194 | H39: sarah sjoestroem - 194 | I39: 241
D40: 1 | E40: dimanche, 4 août 2024 | F40: Sarah SJOESTROEM | G40: 194 | H40: sarah sjoestroem - 194 | I40: 240 | J40: 1572557
D41: 1 | E41: samedi, 3 août 2024 | F41: Markus ROOTH | G41: 151 | H41: markus rooth - 151 | I41: 41 | J41: 1878353
...

Sheet 3. Mise en forme
A1: =Variables!$A$1 -> #VALUE!
D3: TITRE DES DONNEES
D4: DATE | E4: FAMILLE PRODUIT | F4: MONTANT | G4: %
D5: 42371 | E5: MONTAGNE | F5: 943.6 | G5: =F5/$F$33 -> 0.056961414
D6: 42371 | E6: EQUITATION | F6: 299.6 | G6: =F6/$F$33 -> 0.018085672
D7: 42371 | E7: SKI | F7: 463.6 | G7: =F7/$F$33 -> 0.027985705
D8: 42371 | E8: CYCLISME | F8: 471.6 | G8: =F8/$F$33 -> 0.028468634
D9: 42371 | E9: EQUITATION | F9: 181.2 | G9: =F9/$F$33 -> 0.01093833
D10: 42371 | E10: EQUITATION | F10: 1266.4 | G10: =F10/$F$33 -> 0.076447578
D11: 42371 | E11: EQUITATION | F11: 898 | G11: =F11/$F$33 -> 0.054208722
D12: 42372 | E12: EQUITATION | F12: 865.6 | G12: =F12/$F$33 -> 0.052252861
D13: 42372 | E13: SKI | F13: 1252.4 | G13: =F13/$F$33 -> 0.075602453
D14: 42372 | E14: PLONGEE | F14: 143.2 | G14: =F14/$F$33 -> 0.0086444198
D15: 42372 | E15: CYCLISME | F15: 832.4 | G15: =F15/$F$33 -> 0.050248708
D16: 42372 | E16: EQUITATION | F16: 97.6 | G16: =F16/$F$33 -> 0.0058917274
D17: 42373 | E17: MONTAGNE | F17: 119.6 | G17: =F17/$F$33 -> 0.0072197808
D18: GROUPE 2
D19: 42373 | E19: PLONGEE | F19: 238.4 | G19: =F19/$F$33 -> 0.014391269
D20: 42374 | E20: EQUITATION | F20: 1158 | G20: =F20/$F$33 -> 0.069903897
D21: 42374 | E21: EQUITATION | F21: 544 | G21: =F21/$F$33 -> 0.032839137
D22: 42376 | E22: CYCLISME | F22: 1244 | G22: =F22/$F$33 -> 0.075095378
D23: 42376 | E23: EQUITATION | F23: 849.6 | G23: =F23/$F$33 -> 0.051287004
D24: 42376 | E24: EQUITATION | F24: 94 | G24: =F24/$F$33 -> 0.0056744096
D25: 42376 | E25: PLONGEE | F25: 1310.8 | G25: =F25/$F$33 -> 0.079127831
D26: 42378 | E26: CYCLISME | F26: 704 | G26: =F26/$F$33 -> 0.042497706
D27: 42379 | E27: EQUITATION | F27: 214.4 | G27: =F27/$F$33 -> 0.012942483
D28: 42380 | E28: MONTAGNE | F28: 300.4 | G28: =F28/$F$33 -> 0.018133964
D29: 42380 | E29: MONTAGNE | F29: 144.8 | G29: =F29/$F$33 -> 0.0087410055
D30: 42380 | E30: PLONGEE | F30: 348.4 | G30: =F30/$F$33 -> 0.021031535
... D32: 42381 | E32: SKI | F32: 1189.6 | G32: =F32/$F$33 -> 0.071811465
E33: TOTAL | F33: =SUM(F5:F32) -> 16565.6

Sheet 4. Sélection de cellules
A1: =Variables!$A$1 -> #VALUE!
D3: TITRE DES DONNEES
D4: DATE | E4: FAMILLE PRODUIT | F4: MONTANT
D5: 42371 | E5: MONTAGNE | F5: 943.6
D6: 42371 | E6: EQUITATION | F6: 299.6
D7: 42371 | E7: SKI | F7: 463.6
D8: 42371 | E8: CYCLISME | F8: 471.6
D9: 42371 | E9: EQUITATION | F9: 181.2
D10: 42371 | E10: EQUITATION | F10: 1266.4
D11: 42371 | E11: EQUITATION | F11: 898
D12: 42372 | E12: EQUITATION | F12: 865.6
D13: 42372 | E13: SKI | F13: 1252.4
D14: 42372 | E14: PLONGEE | F14: 143.2
D15: 42372 | E15: CYCLISME | F15: 832.4
D16: 42372 | E16: EQUITATION | F16: 97.6
D17: 42373 | E17: MONTAGNE | F17: 119.6
D18: GROUPE 2

Sheet 5. Insertion auto
A1: =Variables!$A$1 -> #VALUE!
D3: DATE | E3: SALLE | F3: INDEX
D4: 42371 | E4: SALLE 1 | F4: 100 | H4: Insérez automatiquement les jours de la semaine
H5: mercredi
H8: Insérez automatiquement les mois de l'année
H9: janvier
H10: mai
H13: NOC1-14-4567
H14: NOC1-123-8867
H15: NOC2-451-321
H16: NOC3-23-4498
H17: NOC3-213-4578
H18: NOC1-325-237
H19: NOC2-347-745152
H20: NOC2-8-45874

Sheet 6. Formule-intro
A1: =Variables!A1 -> #VALUE!
D4: 2024
D5: Ventes | G5: TOTAUX
D6: jan | E6: feb | F6: mar | G6: total | H6: TVA | I6: TTC
D7: 510 | E7: 380 | F7: 480
D8: 920 | E8: 320 | F8: 280
D9: 740 | E9: 670 | F9: 790
D10: 410 | E10: 190 | F10: 130
D11: 400 | E11: 950 | F11: 740
D12: 500 | E12: 850 | F12: 890
D13: 270 | E13: 680 | F13: 220
D14: 420 | E14: 700 | F14: 190
D15: 630 | E15: 710 | F15: 490
D16: 240 | E16: 790 | F16: 170
D17: 920 | E17: 220 | F17: 330
D18: 210 | E18: 820 | F18: 540
... D21: 890 | E21: 130 | F21: 860

Sheet I1. Réf rel. et abs.
A1: =Variables!$A$1 -> #VALUE!
K4: PRIX DE VENTE ESTIME
G5: PRODUIT | H5: Matières premières | I5: Main d'œuvre | J5: TOTAL | K5: 0.1 | L5: 0.15 | M5: 0.2 | N5: 0.25 | O5: 0.3 | P5: 0.35 | Q5: 0.4
G6: PRODUIT1 | H6: 600 | I6: 200
G7: PRODUIT2 | H7: 753 | I7: 137
G8: PRODUIT3 | H8: 695 | I8: 231
G9: PRODUIT4 | H9: 742 | I9: 228
G10: PRODUIT5 | H10: 804 | I10: 146
G11: PRODUIT6 | H11: 821 | I11: 152
G12: PRODUIT7 | H12: 617 | I12: 246
G13: PRODUIT8 | H13: 455 | I13: 174
G14: PRODUIT9 | H14: 542 | I14: 193
G15: PRODUIT10 | H15: 649 | I15: 215
G16: PRODUIT11 | H16: 822 | I16: 151
G17: PRODUIT12 | H17: 846 | I17: 124
... G26: PRODUIT21 | H26: 736 | I26: 201
G34: SOLUTION (afficher les lignes ci-dessous)
K35: PRIX DE VENTE ESTIME
G36: PRODUIT | H36: Matières premières | I36: Main d'œuvre | J36: TOTAL | K36: 0.1 | L36: 0.15 | M36: 0.2 | N36: 0.25 | O36: 0.3 | P36: 0.35 | Q36: 0.4
G37: PRODUIT1 | H37: 600 | I37: 200 | J37: =H37+I37 -> 800 | K37: =ROUND($J37*(1+K$5)*(1+TVACH),0) -> 957 | L37: =ROUND($J37*(1+L$5)*(1+TVACH),0) -> 1000 | M37: =ROUND($J37*(1+M$5)*(1+TVACH),0) -> 1044 | N37: =ROUND($J37*(1+N$5)*(1+TVACH),0) -> 1087 | O37: =ROUND($J37*(1+O$5)*(1+TVACH),0) -> 1130 | P37: =ROUND($J37*(1+P$5)*(1+TVACH),0) -> 1174 | Q37: =ROUND($J37*(1+Q$5)*(1+TVACH),0) -> 1217
G38: PRODUIT2 | H38: 753 | I38: 137 | J38: =H38+I38 -> 890 | K38: =ROUND($J38*(1+K$5)*(1+TVACH),0) -> 1064 | L38: =ROUND($J38*(1+L$5)*(1+TVACH),0) -> 1113 | M38: =ROUND($J38*(1+M$5)*(1+TVACH),0) -> 1161 | N38: =ROUND($J38*(1+N$5)*(1+TVACH),0) -> 1209 | O38: =ROUND($J38*(1+O$5)*(1+TVACH),0) -> 1258 | P38: =ROUND($J38*(1+P$5)*(1+TVACH),0) -> 1306 | Q38: =ROUND($J38*(1+Q$5)*(1+TVACH),0) -> 1354
G39: PRODUIT3 | H39: 695 | I39: 231 | J39: =H39+I39 -> 926 | K39: =ROUND($J39*(1+K$5)*(1+TVACH),0) -> 1107 | L39: =ROUND($J39*(1+L$5)*(1+TVACH),0) -> 1158 | M39: =ROUND($J39*(1+M$5)*(1+TVACH),0) -> 1208 | N39: =ROUND($J39*(1+N$5)*(1+TVACH),0) -> 1258 | O39: =ROUND($J39*(1+O$5)*(1+TVACH),0) -> 1309 | P39: =ROUND($J39*(1+P$5)*(1+TVACH),0) -> 1359 | Q39: =ROUND($J39*(1+Q$5)*(1+TVACH),0) -> 1409
G40: PRODUIT4 | H40: 742 | I40: 228 | J40: =H40+I40 -> 970 | K40: =ROUND($J40*(1+K$5)*(1+TVACH),0) -> 1160 | L40: =ROUND($J40*(1+L$5)*(1+TVACH),0) -> 1213 | M40: =ROUND($J40*(1+M$5)*(1+TVACH),0) -> 1265 | N40: =ROUND($J40*(1+N$5)*(1+TVACH),0) -> 1318 | O40: =ROUND($J40*(1+O$5)*(1+TVACH),0) -> 1371 | P40: =ROUND($J40*(1+P$5)*(1+TVACH),0) -> 1423 | Q40: =ROUND($J40*(1+Q$5)*(1+TVACH),0) -> 1476
G41: PRODUIT5 | H41: 804 | I41: 146 | J41: =H41+I41 -> 950 | K41: =ROUND($J41*(1+K$5)*(1+TVACH),0) -> 1136 | L41: =ROUND($J41*(1+L$5)*(1+TVACH),0) -> 1188 | M41: =ROUND($J41*(1+M$5)*(1+TVACH),0) -> 1239 | N41: =ROUND($J41*(1+N$5)*(1+TVACH),0) -> 1291 | O41: =ROUND($J41*(1+O$5)*(1+TVACH),0) -> 1342 | P41: =ROUND($J41*(1+P$5)*(1+TVACH),0) -> 1394 | Q41: =ROUND($J41*(1+Q$5)*(1+TVACH),0) -> 1446
G42: PRODUIT6 | H42: 821 | I42: 152 | J42: =H42+I42 -> 973 | K42: =ROUND($J42*(1+K$5)*(1+TVACH),0) -> 1163 | L42: =ROUND($J42*(1+L$5)*(1+TVACH),0) -> 1216 | M42: =ROUND($J42*(1+M$5)*(1+TVACH),0) -> 1269 | N42: =ROUND($J42*(1+N$5)*(1+TVACH),0) -> 1322 | O42: =ROUND($J42*(1+O$5)*(1+TVACH),0) -> 1375 | P42: =ROUND($J42*(1+P$5)*(1+TVACH),0) -> 1428 | Q42: =ROUND($J42*(1+Q$5)*(1+TVACH),0) -> 1481
G43: PRODUIT7 | H43: 617 | I43: 246 | J43: =H43+I43 -> 863 | K43: =ROUND($J43*(1+K$5)*(1+TVACH),0) -> 1032 | L43: =ROUND($J43*(1+L$5)*(1+TVACH),0) -> 1079 | M43: =ROUND($J43*(1+M$5)*(1+TVACH),0) -> 1126 | N43: =ROUND($J43*(1+N$5)*(1+TVACH),0) -> 1173 | O43: =ROUND($J43*(1+O$5)*(1+TVACH),0) -> 1220 | P43: =ROUND($J43*(1+P$5)*(1+TVACH),0) -> 1266 | Q43: =ROUND($J43*(1+Q$5)*(1+TVACH),0) -> 1313
G44: PRODUIT8 | H44: 455 | I44: 174 | J44: =H44+I44 -> 629 | K44: =ROUND($J44*(1+K$5)*(1+TVACH),0) -> 752 | L44: =ROUND($J44*(1+L$5)*(1+TVACH),0) -> 786 | M44: =ROUND($J44*(1+M$5)*(1+TVACH),0) -> 820 | N44: =ROUND($J44*(1+N$5)*(1+TVACH),0) -> 855 | O44: =ROUND($J44*(1+O$5)*(1+TVACH),0) -> 889 | P44: =ROUND($J44*(1+P$5)*(1+TVACH),0) -> 923 | Q44: =ROUND($J44*(1+Q$5)*(1+TVACH),0) -> 957
G45: PRODUIT9 | H45: 542 | I45: 193 | J45: =H45+I45 -> 735 | K45: =ROUND($J45*(1+K$5)*(1+TVACH),0) -> 879 | L45: =ROUND($J45*(1+L$5)*(1+TVACH),0) -> 919 | M45: =ROUND($J45*(1+M$5)*(1+TVACH),0) -> 959 | N45: =ROUND($J45*(1+N$5)*(1+TVACH),0) -> 999 | O45: =ROUND($J45*(1+O$5)*(1+TVACH),0) -> 1039 | P45: =ROUND($J45*(1+P$5)*(1+TVACH),0) -> 1079 | Q45: =ROUND($J45*(1+Q$5)*(1+TVACH),0) -> 1119
G46: PRODUIT10 | H46: 649 | I46: 215 | J46: =H46+I46 -> 864 | K46: =ROUND($J46*(1+K$5)*(1+TVACH),0) -> 1033 | L46: =ROUND($J46*(1+L$5)*(1+TVACH),0) -> 1080 | M46: =ROUND($J46*(1+M$5)*(1+TVACH),0) -> 1127 | N46: =ROUND($J46*(1+N$5)*(1+TVACH),0) -> 1174 | O46: =ROUND($J46*(1+O$5)*(1+TVACH),0) -> 1221 | P46: =ROUND($J46*(1+P$5)*(1+TVACH),0) -> 1268 | Q46: =ROUND($J46*(1+Q$5)*(1+TVACH),0) -> 1315
G47: PRODUIT11 | H47: 822 | I47: 151 | J47: =H47+I47 -> 973 | K47: =ROUND($J47*(1+K$5)*(1+TVACH),0) -> 1163 | L47: =ROUND($J47*(1+L$5)*(1+TVACH),0) -> 1216 | M47: =ROUND($J47*(1+M$5)*(1+TVACH),0) -> 1269 | N47: =ROUND($J47*(1+N$5)*(1+TVACH),0) -> 1322 | O47: =ROUND($J47*(1+O$5)*(1+TVACH),0) -> 1375 | P47: =ROUND($J47*(1+P$5)*(1+TVACH),0) -> 1428 | Q47: =ROUND($J47*(1+Q$5)*(1+TVACH),0) -> 1481
G48: PRODUIT12 | H48: 846 | I48: 124 | J48: =H48+I48 -> 970 | K48: =ROUND($J48*(1+K$5)*(1+TVACH),0) -> 1160 | L48: =ROUND($J48*(1+L$5)*(1+TVACH),0) -> 1213 | M48: =ROUND($J48*(1+M$5)*(1+TVACH),0) -> 1265 | N48: =ROUND($J48*(1+N$5)*(1+TVACH),0) -> 1318 | O48: =ROUND($J48*(1+O$5)*(1+TVACH),0) -> 1371 | P48: =ROUND($J48*(1+P$5)*(1+TVACH),0) -> 1423 | Q48: =ROUND($J48*(1+Q$5)*(1+TVACH),0) -> 1476
... G57: PRODUIT21 | H57: 736 | I57: 201 | J57: =H57+I57 -> 937 | K57: =ROUND($J57*(1+K$5)*(1+TVACH),0) -> 1120 | L57: =ROUND($J57*(1+L$5)*(1+TVACH),0) -> 1171 | M57: =ROUND($J57*(1+M$5)*(1+TVACH),0) -> 1222 | N57: =ROUND($J57*(1+N$5)*(1+TVACH),0) -> 1273 | O57: =ROUND($J57*(1+O$5)*(1+TVACH),0) -> 1324 | P57: =ROUND($J57*(1+P$5)*(1+TVACH),0) -> 1375 | Q57: =ROUND($J57*(1+Q$5)*(1+TVACH),0) -> 1426

Sheet 7. Noms définis
A1: =Variables!$A$1 -> #VALUE!
D4: 2024
D5: Ventes | G5: TOTAUX
D6: jan | E6: feb | F6: mar | G6: total | H6: TVA | I6: TTC
D7: 510 | E7: 380 | F7: 480
D8: 920 | E8: 320 | F8: 280
D9: 740 | E9: 670 | F9: 790
D10: 410 | E10: 190 | F10: 130
D11: 400 | E11: 950 | F11: 740
D12: 500 | E12: 850 | F12: 890
D13: 270 | E13: 680 | F13: 220
D14: 420 | E14: 700 | F14: 190
D15: 630 | E15: 710 | F15: 490
D16: 240 | E16: 790 | F16: 170
D17: 920 | E17: 220 | F17: 330
D18: 210 | E18: 820 | F18: 540
... D21: 890 | E21: 130 | F21: 860

Sheet 8. Feuilles
A1: =Variables!$A$1 -> #VALUE!

Sheet 9. TRI
A1: =Variables!$A$1 -> #VALUE!
D3: medal_code | E3: medal_date | F3: name | G3: NOCID | H3: DisciplineID | I3: AthleteID
D4: 1 | E4: mardi, 30 juillet 2024 | F4: Daniel WIFFEN | G4: 99 | H4: 261 | I4: 1539969
D5: 1 | E5: lundi, 29 juillet 2024 | F5: David POPOVICI | G5: 171 | H5: 259 | I5: 1543549
D6: 1 | E6: samedi, 10 août 2024 | F6: Arian SALIMI | G6: 98 | H6: 283 | I6: 1536045
D7: 1 | E7: samedi, 3 août 2024 | F7: Julien ALFRED | G7: 122 | H7: 45 | I7: 1537325
D8: 1 | E8: mercredi, 31 juillet 2024 | F8: Lasha BEKAURI | G8: 80 | H8: 179 | I8: 1548817
D9: 1 | E9: mercredi, 31 juillet 2024 | F9: Cassandre BEAUGRAND | G9: 72 | H9: 295 | I9: 1543963
D10: 1 | E10: dimanche, 11 août 2024 | F10: Akhmed TAZHUDINOV | G10: 31 | H10: 328 | I10: 1540305
D11: 1 | E11: vendredi, 9 août 2024 | F11: Imane KHELIF | G11: 5 | H11: 92 | I11: 1540353
D12: 1 | E12: dimanche, 4 août 2024 | F12: Kaylia NEMOUR | G12: 5 | H12: 17
D13: 1 | E13: lundi, 5 août 2024 | F13: Alice D'AMATO | G13: 104 | H13: 18 | I13: 1551061
D14: 1 | E14: vendredi, 9 août 2024 | F14: Toby ROBERTS | G14: 77 | H14: 236 | I14: 1544218
D15: 1 | E15: mercredi, 7 août 2024 | F15: Mohammadhadi SARAVI | G15: 98 | H15: 316 | I15: 1544897
D16: 1 | E16: jeudi, 8 août 2024 | F16: Saeid ESMAEILI LEIVESI | G16: 98 | H16: 313 | I16: 1544928
D17: 1 | E17: samedi, 10 août 2024 | F17: Lasha TALAKHADZE | G17: 80 | H17: 311 | I17: 1551443
D18: 1 | E18: samedi, 10 août 2024 | F18: Geno PETRIASHVILI | G18: 80 | H18: 329
D19: 1 | E19: mardi, 6 août 2024 | F19: Kellie HARRINGTON | G19: 99 | H19: 91 | I19: 1555098
D20: 1 | E20: mercredi, 7 août 2024 | F20: Soufiane EL BAKKALI | G20: 128 | H20: 30 | I20: 1555372
D21: 1 | E21: mercredi, 7 août 2024 | F21: Erislandy ALVAREZ BORGES | G21: 54 | H21: 83 | I21: 1555537
D22: 1 | E22: jeudi, 8 août 2024 | F22: Hasanboy DUSMATOV | G22: 216 | H22: 81 | I22: 1556045
D23: 1 | E23: samedi, 10 août 2024 | F23: Abdumalik KHALOKOV | G23: 216 | H23: 82 | I23: 1556049
D24: 1 | E24: vendredi, 9 août 2024 | F24: Asadkhuja MUYDINKHUJAEV | G24: 216 | H24: 84 | I24: 1556797
D25: 1 | E25: vendredi, 9 août 2024 | F25: Lazizbek MULLOJONOV | G25: 216 | H25: 86 | I25: 1556860
D26: 1 | E26: samedi, 10 août 2024 | F26: Bakhodir JALOLOV | G26: 216 | H26: 87 | I26: 1556869
D27: 1 | E27: vendredi, 9 août 2024 | F27: Magomed Eldarovitch RAMAZANOV | G27: 33 | H27: 327 | I27: 1556873
D28: 1 | E28: jeudi, 8 août 2024 | F28: Semen Sergeevich NOVIKOV | G28: 33 | H28: 315 | I28: 1559471
D29: 1 | E29: samedi, 10 août 2024 | F29: Razambek Salambekovitch JAMALOV | G29: 216 | H29: 326 | I29: 1562164
D30: 1 | E30: mercredi, 7 août 2024 | F30: Aleksandra MIROSLAW | G30: 164 | H30: 235 | I30: 1563327
D31: 1 | E31: mercredi, 7 août 2024 | F31: Oleksandr KHYZHNIAK | G31: 212 | H31: 85
D32: 1 | E32: vendredi, 9 août 2024 | F32: Valentin BONTUS | G32: 14 | H32: 206 | I32: 1566437
D33: 1 | E33: dimanche, 28 juillet 2024 | F33: Diyora KELDIYOROVA | G33: 216 | H33: 169 | I33: 1566997
D34: 1 | E34: lundi, 5 août 2024 | F34: Kauli VAAST | G34: 72 | H34: 238 | I34: 1567361
D35: 1 | E35: lundi, 5 août 2024 | F35: Armand DUPLANTIS | G35: 194 | H35: 34 | I35: 1569203
D36: 1 | E36: mardi, 6 août 2024 | F36: Mijain LOPEZ NUNEZ | G36: 54 | H36: 317 | I36: 1571506
D37: 1 | E37: dimanche, 4 août 2024 | F37: Yaroslava MAHUCHIKH | G37: 212 | H37: 56 | I37: 1571559
D38: 1 | E38: vendredi, 9 août 2024 | F38: Viviana MARTON | G38: 93 | H38: 286 | I38: 1572318
D39: 1 | E39: mercredi, 31 juillet 2024 | F39: Sarah SJOESTROEM | G39: 194 | H39: 241
D40: 1 | E40: dimanche, 4 août 2024 | F40: Sarah SJOESTROEM | G40: 194 | H40: 240 | I40: 1572557
D41: 1 | E41: samedi, 3 août 2024 | F41: Markus ROOTH | G41: 151 | H41: 41 | I41: 1878353
...

Sheet 10. FILTRE
A1: =Variables!$A$1 -> #VALUE!
D3: medal_code | E3: medal_date | F3: name | G3: NOCID | H3: DisciplineID | I3: AthleteID
D4: 1 | E4: 45503 | F4: Daniel WIFFEN | G4: 99 | H4: 261 | I4: 1539969
D5: 1 | E5: 45502 | F5: David POPOVICI | G5: 171 | H5: 259 | I5: 1543549
D6: 1 | E6: 45514 | F6: Arian SALIMI | G6: 98 | H6: 283 | I6: 1536045
D7: 1 | E7: 45507 | F7: Julien ALFRED | G7: 122 | H7: 45 | I7: 1537325
D8: 1 | E8: 45504 | F8: Lasha BEKAURI | G8: 80 | H8: 179 | I8: 1548817
D9: 1 | E9: 45504 | F9: Cassandre BEAUGRAND | G9: 72 | H9: 295 | I9: 1543963
D10: 1 | E10: 45515 | F10: Akhmed TAZHUDINOV | G10: 31 | H10: 328 | I10: 1540305
D11: 1 | E11: 45513 | F11: Imane KHELIF | G11: 5 | H11: 92 | I11: 1540353
D12: 1 | E12: 45508 | F12: Kaylia NEMOUR | G12: 5 | H12: 17
D13: 1 | E13: 45509 | F13: Alice D'AMATO | G13: 104 | H13: 18 | I13: 1551061
D14: 1 | E14: 45513 | F14: Toby ROBERTS | G14: 77 | H14: 236 | I14: 1544218
D15: 1 | E15: 45511 | F15: Mohammadhadi SARAVI | G15: 98 | H15: 316 | I15: 1544897
D16: 1 | E16: 45512 | F16: Saeid ESMAEILI LEIVESI | G16: 98 | H16: 313 | I16: 1544928
D17: 1 | E17: 45514 | F17: Lasha TALAKHADZE | G17: 80 | H17: 311 | I17: 1551443
D18: 1 | E18: 45514 | F18: Geno PETRIASHVILI | G18: 80 | H18: 329
D19: 1 | E19: 45510 | F19: Kellie HARRINGTON | G19: 99 | H19: 91 | I19: 1555098
D20: 1 | E20: 45511 | F20: Soufiane EL BAKKALI | G20: 128 | H20: 30 | I20: 1555372
D21: 1 | E21: 45511 | F21: Erislandy ALVAREZ BORGES | G21: 54 | H21: 83 | I21: 1555537
D22: 1 | E22: 45512 | F22: Hasanboy DUSMATOV | G22: 216 | H22: 81 | I22: 1556045
D23: 1 | E23: 45514 | F23: Abdumalik KHALOKOV | G23: 216 | H23: 82 | I23: 1556049
D24: 1 | E24: 45513 | F24: Asadkhuja MUYDINKHUJAEV | G24: 216 | H24: 84 | I24: 1556797
D25: 1 | E25: 45513 | F25: Lazizbek MULLOJONOV | G25: 216 | H25: 86 | I25: 1556860
D26: 1 | E26: 45514 | F26: Bakhodir JALOLOV | G26: 216 | H26: 87 | I26: 1556869
D27: 1 | E27: 45513 | F27: Magomed Eldarovitch RAMAZANOV | G27: 33 | H27: 327 | I27: 1556873
D28: 1 | E28: 45512 | F28: Semen Sergeevich NOVIKOV | G28: 33 | H28: 315 | I28: 1559471
D29: 1 | E29: 45514 | F29: Razambek Salambekovitch JAMALOV | G29: 216 | H29: 326 | I29: 1562164
D30: 1 | E30: 45511 | F30: Aleksandra MIROSLAW | G30: 164 | H30: 235 | I30: 1563327
D31: 1 | E31: 45511 | F31: Oleksandr KHYZHNIAK | G31: 212 | H31: 85
D32: 1 | E32: 45513 | F32: Valentin BONTUS | G32: 14 | H32: 206 | I32: 1566437
D33: 1 | E33: 45501 | F33: Diyora KELDIYOROVA | G33: 216 | H33: 169 | I33: 1566997
D34: 1 | E34: 45509 | F34: Kauli VAAST | G34: 72 | H34: 238 | I34: 1567361
D35: 1 | E35: 45509 | F35: Armand DUPLANTIS | G35: 194 | H35: 34 | I35: 1569203
D36: 1 | E36: 45510 | F36: Mijain LOPEZ NUNEZ | G36: 54 | H36: 317 | I36: 1571506
D37: 1 | E37: 45508 | F37: Yaroslava MAHUCHIKH | G37: 212 | H37: 56 | I37: 1571559
D38: 1 | E38: 45513 | F38: Viviana MARTON | G38: 93 | H38: 286 | I38: 1572318
D39: 1 | E39: 45504 | F39: Sarah SJOESTROEM | G39: 194 | H39: 241
D40: 1 | E40: 45508 | F40: Sarah SJOESTROEM | G40: 194 | H40: 240 | I40: 1572557
D41: 1 | E41: 45507 | F41: Markus ROOTH | G41: 151 | H41: 41 | I41: 1878353
...

Sheet 11. RECHERCHE
A1: =Variables!$A$1 -> #VALUE!
D3: medal_code | E3: medal_date | F3: name | G3: NOCID | H3: DisciplineID | I3: AthleteID
D4: 1 | E4: 45503 | F4: Daniel WIFFEN | G4: 99 | H4: 261 | I4: 1539969 | J4: {=_xlfn.SWITCH(D4,1,"OR",2,"ARGENT",3,"BRONZE")} -> OR
D5: 1 | E5: 45502 | F5: David POPOVICI | G5: 171 | H5: 259 | I5: 1543549 | J5: {=_xlfn.SWITCH(D5,1,"OR",2,"ARGENT",3,"BRONZE")} -> OR
D6: 1 | E6: 45514 | F6: Arian SALIMI | G6: 98 | H6: 283 | I6: 1536045 | J6: {=_xlfn.SWITCH(D6,1,"OR",2,"ARGENT",3,"BRONZE")} -> OR
D7: 1 | E7: 45507 | F7: Julien ALFRED | G7: 122 | H7: 45 | I7: 1537325 | J7: {=_xlfn.SWITCH(D7,1,"OR",2,"ARGENT",3,"BRONZE")} -> OR
D8: 1 | E8: 45504 | F8: Lasha BEKAURI | G8: 80 | H8: 179 | I8: 1548817 | J8: {=_xlfn.SWITCH(D8,1,"OR",2,"ARGENT",3,"BRONZE")} -> OR
D9: 1 | E9: 45504 | F9: Cassandre BEAUGRAND | G9: 72 | H9: 295 | I9: 1543963 | J9: {=_xlfn.SWITCH(D9,1,"OR",2,"ARGENT",3,"BRONZE")} -> OR
D10: 2 | E10: 45515 | F10: Akhmed TAZHUDINOV | G10: 31 | H10: 328 | I10: 1540305 | J10: {=_xlfn.SWITCH(D10,1,"OR",2,"ARGENT",3,"BRONZE")} -> ARGENT
D11: 1 | E11: 45513 | F11: Imane KHELIF | G11: 5 | H11: 92 | I11: 1540353 | J11: {=_xlfn.SWITCH(D11,1,"OR",2,"ARGENT",3,"BRONZE")} -> OR
D12: 2 | E12: 45508 | F12: Kaylia NEMOUR | G12: 5 | H12: 17 | J12: {=_xlfn.SWITCH(D12,1,"OR",2,"ARGENT",3,"BRONZE")} -> ARGENT
D13: 1 | E13: 45509 | F13: Alice D'AMATO | G13: 104 | H13: 18 | I13: 1551061 | J13: {=_xlfn.SWITCH(D13,1,"OR",2,"ARGENT",3,"BRONZE")} -> OR
D14: 2 | E14: 45513 | F14: Toby ROBERTS | G14: 77 | H14: 236 | I14: 1544218 | J14: {=_xlfn.SWITCH(D14,1,"OR",2,"ARGENT",3,"BRONZE")} -> ARGENT
D15: 1 | E15: 45511 | F15: Mohammadhadi SARAVI | G15: 98 | H15: 316 | I15: 1544897 | J15: {=_xlfn.SWITCH(D15,1,"OR",2,"ARGENT",3,"BRONZE")} -> OR
D16: 3 | E16: 45512 | F16: Saeid ESMAEILI LEIVESI | G16: 98 | H16: 313 | I16: 1544928 | J16: {=_xlfn.SWITCH(D16,1,"OR",2,"ARGENT",3,"BRONZE")} -> BRONZE
D17: 1 | E17: 45514 | F17: Lasha TALAKHADZE | G17: 80 | H17: 311 | I17: 1551443 | J17: {=_xlfn.SWITCH(D17,1,"OR",2,"ARGENT",3,"BRONZE")} -> OR
D18: 3 | E18: 45514 | F18: Geno PETRIASHVILI | G18: 80 | H18: 329 | J18: {=_xlfn.SWITCH(D18,1,"OR",2,"ARGENT",3,"BRONZE")} -> BRONZE
D19: 1 | E19: 45510 | F19: Kellie HARRINGTON | G19: 99 | H19: 91 | I19: 1555098 | J19: {=_xlfn.SWITCH(D19,1,"OR",2,"ARGENT",3,"BRONZE")} -> OR
D20: 1 | E20: 45511 | F20: Soufiane EL BAKKALI | G20: 128 | H20: 30 | I20: 1555372 | J20: {=_xlfn.SWITCH(D20,1,"OR",2,"ARGENT",3,"BRONZE")} -> OR
D21: 3 | E21: 45511 | F21: Erislandy ALVAREZ BORGES | G21: 54 | H21: 83 | I21: 1555537 | J21: {=_xlfn.SWITCH(D21,1,"OR",2,"ARGENT",3,"BRONZE")} -> BRONZE
D22: 1 | E22: 45512 | F22: Hasanboy DUSMATOV | G22: 216 | H22: 81 | I22: 1556045 | J22: {=_xlfn.SWITCH(D22,1,"OR",2,"ARGENT",3,"BRONZE")} -> OR
D23: 1 | E23: 45514 | F23: Abdumalik KHALOKOV | G23: 216 | H23: 82 | I23: 1556049 | J23: {=_xlfn.SWITCH(D23,1,"OR",2,"ARGENT",3,"BRONZE")} -> OR
D24: 3 | E24: 45513 | F24: Asadkhuja MUYDINKHUJAEV | G24: 216 | H24: 84 | I24: 1556797 | J24: {=_xlfn.SWITCH(D24,1,"OR",2,"ARGENT",3,"BRONZE")} -> BRONZE
D25: 1 | E25: 45513 | F25: Lazizbek MULLOJONOV | G25: 216 | H25: 86 | I25: 1556860 | J25: {=_xlfn.SWITCH(D25,1,"OR",2,"ARGENT",3,"BRONZE")} -> OR
D26: 3 | E26: 45514 | F26: Bakhodir JALOLOV | G26: 216 | H26: 87 | I26: 1556869 | J26: {=_xlfn.SWITCH(D26,1,"OR",2,"ARGENT",3,"BRONZE")} -> BRONZE
D27: 3 | E27: 45513 | F27: Magomed Eldarovitch RAMAZANOV | G27: 33 | H27: 327 | I27: 1556873 | J27: {=_xlfn.SWITCH(D27,1,"OR",2,"ARGENT",3,"BRONZE")} -> BRONZE
D28: 3 | E28: 45512 | F28: Semen Sergeevich NOVIKOV | G28: 33 | H28: 315 | I28: 1559471 | J28: {=_xlfn.SWITCH(D28,1,"OR",2,"ARGENT",3,"BRONZE")} -> BRONZE
D29: 3 | E29: 45514 | F29: Razambek Salambekovitch JAMALOV | G29: 216 | H29: 326 | I29: 1562164 | J29: {=_xlfn.SWITCH(D29,1,"OR",2,"ARGENT",3,"BRONZE")} -> BRONZE
D30: 1 | E30: 45511 | F30: Aleksandra MIROSLAW | G30: 164 | H30: 235 | I30: 1563327 | J30: {=_xlfn.SWITCH(D30,1,"OR",2,"ARGENT",3,"BRONZE")} -> OR
D31: 2 | E31: 45511 | F31: Oleksandr KHYZHNIAK | G31: 212 | H31: 85 | J31: {=_xlfn.SWITCH(D31,1,"OR",2,"ARGENT",3,"BRONZE")} -> ARGENT
D32: 1 | E32: 45513 | F32: Valentin BONTUS | G32: 14 | H32: 206 | I32: 1566437 | J32: {=_xlfn.SWITCH(D32,1,"OR",2,"ARGENT",3,"BRONZE")} -> OR
D33: 1 | E33: 45501 | F33: Diyora KELDIYOROVA | G33: 216 | H33: 169 | I33: 1566997 | J33: {=_xlfn.SWITCH(D33,1,"OR",2,"ARGENT",3,"BRONZE")} -> OR
D34: 1 | E34: 45509 | F34: Kauli VAAST | G34: 72 | H34: 238 | I34: 1567361 | J34: {=_xlfn.SWITCH(D34,1,"OR",2,"ARGENT",3,"BRONZE")} -> OR
D35: 2 | E35: 45509 | F35: Armand DUPLANTIS | G35: 194 | H35: 34 | I35: 1569203 | J35: {=_xlfn.SWITCH(D35,1,"OR",2,"ARGENT",3,"BRONZE")} -> ARGENT
D36: 3 | E36: 45510 | F36: Mijain LOPEZ NUNEZ | G36: 54 | H36: 317 | I36: 1571506 | J36: {=_xlfn.SWITCH(D36,1,"OR",2,"ARGENT",3,"BRONZE")} -> BRONZE
D37: 3 | E37: 45508 | F37: Yaroslava MAHUCHIKH | G37: 212 | H37: 56 | I37: 1571559 | J37: {=_xlfn.SWITCH(D37,1,"OR",2,"ARGENT",3,"BRONZE")} -> BRONZE
D38: 3 | E38: 45513 | F38: Viviana MARTON | G38: 93 | H38: 286 | I38: 1572318 | J38: {=_xlfn.SWITCH(D38,1,"OR",2,"ARGENT",3,"BRONZE")} -> BRONZE
D39: 2 | E39: 45504 | F39: Sarah SJOESTROEM | G39: 194 | H39: 241 | J39: {=_xlfn.SWITCH(D39,1,"OR",2,"ARGENT",3,"BRONZE")} -> ARGENT
D40: 2 | E40: 45508 | F40: Sarah SJOESTROEM | G40: 194 | H40: 240 | I40: 1572557 | J40: {=_xlfn.SWITCH(D40,1,"OR",2,"ARGENT",3,"BRONZE")} -> ARGENT
D41: 1 | E41: 45507 | F41: Markus ROOTH | G41: 151 | H41: 41 | I41: 1878353 | J41: {=_xlfn.SWITCH(D41,1,"OR",2,"ARGENT",3,"BRONZE")} -> OR
...

Sheet 12. TABLEAU + GRAPHE
A1: =Variables!$A$1 -> #VALUE!
A4: Plage de cellules | H4: Tableau Excel
A6: Magasin | B6: jan | C6: feb | D6: mar | E6: TOTAL | F6: TOTAL TTC | H6: Magasin | I6: jan | J6: feb | K6: mar | L6: TOTAL | M6: TOTAL TTC
A7: Magasin1 | B7: 100 | C7: 200 | D7: 300 | E7: =SUM(B7:D7) -> 600 | F7: ='12. TABLEAU + GRAPHE'!E7*(1+tax10pc) -> 660 | H7: Magasin1 | I7: 100 | J7: 200 | K7: 300 | L7: =SUM(I7:K7) -> 600 | M7: ='12. TABLEAU + GRAPHE'!L7*(1+tax10pc) -> 660
A8: Magasin2 | B8: 110 | C8: 205 | D8: 302 | E8: =SUM(B8:D8) -> 617 | F8: ='12. TABLEAU + GRAPHE'!E8*(1+tax10pc) -> 678.7 | H8: Magasin2 | I8: 110 | J8: 205 | K8: 302 | L8: =SUM(I8:K8) -> 617 | M8: ='12. TABLEAU + GRAPHE'!L8*(1+tax10pc) -> 678.7
A9: Magasin3 | B9: 120 | C9: 210 | D9: 304 | E9: =SUM(B9:D9) -> 634 | F9: ='12. TABLEAU + GRAPHE'!E9*(1+tax10pc) -> 697.4 | H9: Magasin3 | I9: 120 | J9: 210 | K9: 304 | L9: =SUM(I9:K9) -> 634 | M9: ='12. TABLEAU + GRAPHE'!L9*(1+tax10pc) -> 697.4
A10: Magasin4 | B10: 130 | C10: 215 | D10: 306 | E10: =SUM(B10:D10) -> 651 | F10: ='12. TABLEAU + GRAPHE'!E10*(1+tax10pc) -> 716.1 | H10: Magasin4 | I10: 130 | J10: 215 | K10: 306 | L10: =SUM(I10:K10) -> 651 | M10: ='12. TABLEAU + GRAPHE'!L10*(1+tax10pc) -> 716.1
A11: Magasin5 | B11: 140 | C11: 220 | D11: 308 | E11: =SUM(B11:D11) -> 668 | F11: ='12. TABLEAU + GRAPHE'!E11*(1+tax10pc) -> 734.8 | H11: Magasin5 | I11: 140 | J11: 220 | K11: 308 | L11: =SUM(I11:K11) -> 668 | M11: ='12. TABLEAU + GRAPHE'!L11*(1+tax10pc) -> 734.8
A12: Magasin6 | B12: 150 | C12: 225 | D12: 310 | E12: =SUM(B12:D12) -> 685 | F12: ='12. TABLEAU + GRAPHE'!E12*(1+tax10pc) -> 753.5 | H12: Magasin6 | I12: 150 | J12: 225 | K12: 310 | L12: =SUM(I12:K12) -> 685 | M12: ='12. TABLEAU + GRAPHE'!L12*(1+tax10pc) -> 753.5
A13: Magasin7 | B13: 160 | C13: 230 | D13: 312 | E13: =SUM(B13:D13) -> 702 | F13: ='12. TABLEAU + GRAPHE'!E13*(1+tax10pc) -> 772.2 | H13: Magasin7 | I13: 160 | J13: 230 | K13: 312 | L13: =SUM(I13:K13) -> 702 | M13: ='12. TABLEAU + GRAPHE'!L13*(1+tax10pc) -> 772.2
A14: Magasin8 | B14: 170 | C14: 235 | D14: 314 | E14: =SUM(B14:D14) -> 719 | F14: ='12. TABLEAU + GRAPHE'!E14*(1+tax10pc) -> 790.9 | H14: Magasin8 | I14: 170 | J14: 235 | K14: 314 | L14: =SUM(I14:K14) -> 719 | M14: ='12. TABLEAU + GRAPHE'!L14*(1+tax10pc) -> 790.9
A15: Magasin9 | B15: 180 | C15: 240 | D15: 316 | E15: =SUM(B15:D15) -> 736 | F15: ='12. TABLEAU + GRAPHE'!E15*(1+tax10pc) -> 809.6 | H15: Magasin9 | I15: 180 | J15: 240 | K15: 316 | L15: =SUM(I15:K15) -> 736 | M15: ='12. TABLEAU + GRAPHE'!L15*(1+tax10pc) -> 809.6
A16: Magasin10 | B16: 190 | C16: 245 | D16: 318 | E16: =SUM(B16:D16) -> 753 | F16: ='12. TABLEAU + GRAPHE'!E16*(1+tax10pc) -> 828.3 | H16: Magasin10 | I16: 190 | J16: 245 | K16: 318 | L16: =SUM(I16:K16) -> 753 | M16: ='12. TABLEAU + GRAPHE'!L16*(1+tax10pc) -> 828.3
A17: Magasin11 | B17: 200 | C17: 250 | D17: 320 | E17: =SUM(B17:D17) -> 770 | F17: ='12. TABLEAU + GRAPHE'!E17*(1+tax10pc) -> 847 | H17: Magasin11 | I17: 200 | J17: 250 | K17: 320 | L17: =SUM(I17:K17) -> 770 | M17: ='12. TABLEAU + GRAPHE'!L17*(1+tax10pc) -> 847
A18: Magasin12 | B18: 210 | C18: 255 | D18: 322 | E18: =SUM(B18:D18) -> 787 | F18: ='12. TABLEAU + GRAPHE'!E18*(1+tax10pc) -> 865.7 | H18: Magasin12 | I18: 210 | J18: 255 | K18: 322 | L18: =SUM(I18:K18) -> 787 | M18: ='12. TABLEAU + GRAPHE'!L18*(1+tax10pc) -> 865.7
... A20: Magasin14 | B20: 230 | C20: 265 | D20: 326 | E20: =SUM(B20:D20) -> 821 | F20: ='12. TABLEAU + GRAPHE'!E20*(1+tax10pc) -> 903.1 | H20: Magasin14 | I20: 230 | J20: 265 | K20: 326 | L20: =SUM(I20:K20) -> 821 | M20: ='12. TABLEAU + GRAPHE'!L20*(1+tax10pc) -> 903.1
A32: Nouvelles données
A33: Magasin24 | B33: 155 | C33: 112 | D33: 188
A34: Magasin25 | B34: 165 | C34: 225 | D34: 152
A35: Magasin26 | B35: 190 | C35: 214 | D35: 245
A36: Magasin27 | B36: 210 | C36: 258 | D36: 354
A37: Magasin28 | B37: 224 | C37: 301 | D37: 321
A38: Magasin29 | B38: 290 | C38: 340 | D38: 365
A39: Magasin30 | B39: 190 | C39: 170 | D39: 300

Sheet Variables
A1: #VALUE!
A2: TAX | B2: 0.08
G3: CH | H3: 0.087
A4: TAX | B4: 0.1 | G4: US | H4: 0.1
G5: FR | H5: 0.198
A6: TAX | B6: 0.12 | G6: D | H6: 0.08
G7: IT | H7: 0.09
A8: TAX | B8: 0.1 | G8: GB | H8: 0.098
B10: Liste cantons
B11: Vaud
B12: Genève
B13: Berne
B14: Zurich
B15: Fribourg

Sheet TBL+XLOOKUP
A1: COUNTRY | B1: jan | C1: feb | D1: mar | E1: TOTAL | F1: TOTAL TTC
A2: CH | B2: 100 | C2: 200 | D2: 300 | E2: =SUM(B2:D2) -> 600 | F2: =tbl_xlookup[[#This Row],[TOTAL]]*(1+_xlfn.XLOOKUP(tbl_xlookup[[#This Row],[COUNTRY]],Variables!$G$3:$G$8,Variables!$H$3:$H$8,,0)) -> 652.2
A3: D | B3: 110 | C3: 205 | D3: 302 | E3: =SUM(B3:D3) -> 617 | F3: =tbl_xlookup[[#This Row],[TOTAL]]*(1+_xlfn.XLOOKUP(tbl_xlookup[[#This Row],[COUNTRY]],Variables!$G$3:$G$8,Variables!$H$3:$H$8,,0)) -> 666.36
A4: D | B4: 120 | C4: 210 | D4: 304 | E4: =SUM(B4:D4) -> 634 | F4: =tbl_xlookup[[#This Row],[TOTAL]]*(1+_xlfn.XLOOKUP(tbl_xlookup[[#This Row],[COUNTRY]],Variables!$G$3:$G$8,Variables!$H$3:$H$8,,0)) -> 684.72
A5: CH | B5: 130 | C5: 215 | D5: 306 | E5: =SUM(B5:D5) -> 651 | F5: =tbl_xlookup[[#This Row],[TOTAL]]*(1+_xlfn.XLOOKUP(tbl_xlookup[[#This Row],[COUNTRY]],Variables!$G$3:$G$8,Variables!$H$3:$H$8,,0)) -> 707.637
A6: CH | B6: 140 | C6: 220 | D6: 308 | E6: =SUM(B6:D6) -> 668 | F6: =tbl_xlookup[[#This Row],[TOTAL]]*(1+_xlfn.XLOOKUP(tbl_xlookup[[#This Row],[COUNTRY]],Variables!$G$3:$G$8,Variables!$H$3:$H$8,,0)) -> 726.116
A7: US | B7: 150 | C7: 225 | D7: 310 | E7: =SUM(B7:D7) -> 685 | F7: =tbl_xlookup[[#This Row],[TOTAL]]*(1+_xlfn.XLOOKUP(tbl_xlookup[[#This Row],[COUNTRY]],Variables!$G$3:$G$8,Variables!$H$3:$H$8,,0)) -> 753.5
A8: US | B8: 160 | C8: 230 | D8: 312 | E8: =SUM(B8:D8) -> 702 | F8: =tbl_xlookup[[#This Row],[TOTAL]]*(1+_xlfn.XLOOKUP(tbl_xlookup[[#This Row],[COUNTRY]],Variables!$G$3:$G$8,Variables!$H$3:$H$8,,0)) -> 772.2
A9: GB | B9: 170 | C9: 235 | D9: 314 | E9: =SUM(B9:D9) -> 719 | F9: =tbl_xlookup[[#This Row],[TOTAL]]*(1+_xlfn.XLOOKUP(tbl_xlookup[[#This Row],[COUNTRY]],Variables!$G$3:$G$8,Variables!$H$3:$H$8,,0)) -> 789.462
A10: GB | B10: 180 | C10: 240 | D10: 316 | E10: =SUM(B10:D10) -> 736 | F10: =tbl_xlookup[[#This Row],[TOTAL]]*(1+_xlfn.XLOOKUP(tbl_xlookup[[#This Row],[COUNTRY]],Variables!$G$3:$G$8,Variables!$H$3:$H$8,,0)) -> 808.128
A11: GB | B11: 190 | C11: 245 | D11: 318 | E11: =SUM(B11:D11) -> 753 | F11: =tbl_xlookup[[#This Row],[TOTAL]]*(1+_xlfn.XLOOKUP(tbl_xlookup[[#This Row],[COUNTRY]],Variables!$G$3:$G$8,Variables!$H$3:$H$8,,0)) -> 826.794
A12: CH | B12: 200 | C12: 250 | D12: 320 | E12: =SUM(B12:D12) -> 770 | F12: =tbl_xlookup[[#This Row],[TOTAL]]*(1+_xlfn.XLOOKUP(tbl_xlookup[[#This Row],[COUNTRY]],Variables!$G$3:$G$8,Variables!$H$3:$H$8,,0)) -> 836.99
A13: CH | B13: 210 | C13: 255 | D13: 322 | E13: =SUM(B13:D13) -> 787 | F13: =tbl_xlookup[[#This Row],[TOTAL]]*(1+_xlfn.XLOOKUP(tbl_xlookup[[#This Row],[COUNTRY]],Variables!$G$3:$G$8,Variables!$H$3:$H$8,,0)) -> 855.469
... A24: FR | B24: 190 | C24: 245 | D24: 318 | E24: =SUM(B24:D24) -> 753 | F24: =tbl_xlookup[[#This Row],[TOTAL]]*(1+_xlfn.XLOOKUP(tbl_xlookup[[#This Row],[COUNTRY]],Variables!$G$3:$G$8,Variables!$H$3:$H$8,,0)) -> 902.094
