Workbook
Name Createlink: _xlfn.LAMBDA(_xlpm.sheet,_xlpm.label, HYPERLINK("#'" & _xlpm.sheet & "'!A1", _xlpm.label))
Name eng_flag: TRAD!$C$3=1
Name FiscalQLookupTable: {1,3;4,4;7,1;10,2}
Name FiscalQuarter: _xlfn.LAMBDA(_xlpm.Date,"Q" & LOOKUP(MONTH(_xlpm.Date), {1,3;4,4;7,1;10,2}))
Name lst_moiscourt: TRAD!$E$8:$E$19
Name lst_moislong: TRAD!$F$8:$F$19
Name lst_monthlong: TRAD!$H$8:$H$19
Name lst_monthShort: TRAD!$G$8:$G$19
Name RemoveNumbersFromText: _xlfn.LAMBDA(_xlpm.text,TRIM(_xlfn.REDUCE(_xlpm.text, _xlfn.SEQUENCE(10, , 0), _xlfn.LAMBDA(_xlpm.i,_xlpm.a, SUBSTITUTE(_xlpm.i, _xlpm.a, "")))))
Name ShowFormulas: _xlfn.LAMBDA(_xlpm.reference,IFERROR(_xlfn.TOCOL(ADDRESS(ROW(_xlpm.reference), COLUMN(_xlpm.reference), 4) & ": " & _xlfn.FORMULATEXT(_xlpm.reference), 2), ""))
Name SpaceBeforeCaps: _xlfn.LAMBDA(_xlpm.Text, TRIM(_xlfn.REDUCE( _xlpm.Text, CHAR(_xlfn.SEQUENCE(26, , 65)), _xlfn.LAMBDA(_xlpm.i,_xlpm.a, SUBSTITUTE(_xlpm.i, _xlpm.a, " "&_xlpm.a)))))
Name sq: [1]TRAD!$C$4=1
Name statusList: IF(eng_flag,TRAD!$I$24:$I$30,TRAD!$J$24:$J$30)
Name TranslateDescFromDictionnary: _xlfn.LAMBDA(_xlpm.index,IF(eng_flag,_xlfn.XLOOKUP(_xlpm.index,TRADFUNCTIONS!$A:$A,TRADFUNCTIONS!$D:$D),_xlfn.XLOOKUP(_xlpm.index,TRADFUNCTIONS!$A:$A,TRADFUNCTIONS!$E:$E)))
Name Translatefct: _xlfn.LAMBDA(_xlpm.fct_index,_xlpm.Desc_flag,VLOOKUP(_xlpm.fct_index,[1]!tbl_tradfunctions[#Data],3-sq+_xlpm.Desc_flag*2))
Name TranslateNameFromDictionnary: _xlfn.LAMBDA(_xlpm.index,IF(eng_flag,_xlfn.XLOOKUP(_xlpm.index,TRADFUNCTIONS!$A:$A,TRADFUNCTIONS!$B:$B),_xlfn.XLOOKUP(_xlpm.index,TRADFUNCTIONS!$A:$A,TRADFUNCTIONS!$C:$C)))
Name TranslateTxt: _xlfn.LAMBDA(_xlpm.index,_xlfn.XLOOKUP(_xlpm.index,tbl_txt[ID],IF(eng_flag,tbl_txt[txt_ENG],tbl_txt[txt_FR])))

Sheet TRADFUNCTIONS
A1: ID | B1: KEY_ENG | C1: KEY_FR | D1: DESC_ENG | E1: DESC_FR
A2: 10 | B2: FILTER | C2: FILTRE | D2: Returns an array of values that meet specified conditions. | E2: Renvoie un tableau de valeurs répondant à des critères spécifiés.
A3: 20 | B3: SORT | C3: TRIER | D3: Sorts the contents of an array or range. | E3: Trie le contenu d'un tableau ou d'une plage de cellules.
A4: 30 | B4: SORTBY | C4: TRIERPAR | D4: Sorts an array based on the values in a corresponding array. | E4: Trie un tableau en fonction des valeurs d'un tableau correspondant.
A5: 40 | B5: UNIQUE | C5: UNIQUE | D5: Returns unique values from a range or array. | E5: Renvoie des valeurs uniques à partir d'une plage ou d'un tableau.
A6: 50 | B6: SEQUENCE | C6: SEQUENCE | D6: Generates a sequence of numbers in an array. | E6: Génère une séquence de nombres sous forme de tableau.
A7: 60 | B7: RANDARRAY | C7: TABLEAU.ALEA | D7: Returns an array of random numbers. | E7: Renvoie un tableau de nombres aléatoires.
A8: 70 | B8: ARRAYTOTEXT | C8: TABLEAU.EN.TEXTE | D8: Converts an array to a text string (two formats available). | E8: Convertit un tableau en une chaîne de texte (deux formats possibles).
A9: 80 | B9: EXPAND | C9: ETENDRE | D9: Expands an array to a specified size by adding blank cells or values. | E9: Étend un tableau à une taille spécifiée en ajoutant des cellules vides ou des valeurs.
A10: 90 | B10: TOCOL | C10: DANSCOLONNE | D10: Transforms a range or array into a single column. | E10: Transforme une plage ou un tableau en une seule colonne.
A11: 100 | B11: TOROW | C11: DANSLIGNE | D11: Transforms a range or array into a single row. | E11: Transforme une plage ou un tableau en une seule ligne.
A12: 110 | B12: WRAPCOLS | C12: ORGA.COLS | D12: Arranges values from a single column into multiple columns. | E12: Réorganise des valeurs d'une colonne unique en plusieurs colonnes.
A13: 120 | B13: WRAPROWS | C13: ORGA.LIGNES | D13: Arranges values from a single row into multiple rows. | E13: Réorganise des valeurs d'une ligne unique en plusieurs lignes.
... A97: 1030 | B97: SWITCH | C97: SI.MULTIPLE | D97: Evaluates a single expression and matches it against one or more exact values | E97: Évalue une expression unique et la compare à plusieurs valeurs précises

Sheet TRAD
B1: ENGLISH | C1: FRANÇAIS
J2: sumproduct | K2: The first condition has to be converted from boolean to number thus the *1
B3: Langue choisie: | C3: =_xlfn.XMATCH(BASES!$A$1,$B$1:$C$1,0) -> 2 | K3: La condition doit être convertie de booléen en nombre d'où le *1
A5: ID | B5: txt_ENG | C5: txt_FR
A6: 10 | B6: Formula fundamentals | C6: Fondamentaux d'une formule
A7: 15 | B7: Must start with the '=' sign | C7: Il faut commencer par le signe '=' | E7: lst_moiscourt | F7: lst_moislong | G7: lst_monthShort | H7: lst_monthlong
A8: 16 | B8: Excel can be used as a calculator | C8: Excel peut servir de calculatrice | D8: 1 | E8: janv | F8: janvier | G8: jan | H8: january
A9: 17 | B9: Beware of the use of '(' and ')' | C9: Attention à l’utilisation de « ( » et « ) » | D9: 2 | E9: févr | F9: février | G9: feb | H9: february
A10: 20 | B10: Links to the content of the cell | C10: Liens vers le contenu de la cellule | D10: 3 | E10: mars | F10: mars | G10: mar | H10: march
A11: 30 | B11: Examples | C11: Exemples | D11: 4 | E11: avr | F11: avril | G11: apr | H11: april
A12: 40 | B12: Adding cell values | C12: Ajout des valeurs de cellules | D12: 5 | E12: mai | F12: mai | G12: may | H12: may
A13: 45 | B13: The SUM function to add cell values | C13: La fonction SOMME pour ajouter les valeurs des cellules | D13: 6 | E13: juin | F13: juin | G13: jun | H13: june
A14: 48 | B14: The SUM function to add all cell values in a range | C14: La fonction SOMME additionne toutes les valeurs de cellules dans une plage | D14: 7 | E14: juil | F14: juillet | G14: jul | H14: july
A15: 50 | B15: Calculates the average value of a range of cells | C15: Calcule la valeur moyenne d’une plage de cellules | D15: 8 | E15: août | F15: août | G15: aug | H15: august
A16: 55 | B16: Click inside the formula bar to view the cells used in this formula | C16: Cliquez dans la barre de formule pour voir les cellules utilisées dans cette formule | D16: 9 | E16: sept | F16: septembre | G16: sep | H16: september
A17: 60 | B17: Formulas > Trace Precedent | C17: Formules > Repérer les antécédents | D17: 10 | E17: oct | F17: octobre | G17: oct | H17: october
A18: 61 | B18: Displays arrows to the cells used in the formula | C18: Affiche des flèches vers les cellules utilisées dans la formule | D18: 11 | E18: nov | F18: novembre | G18: nov | H18: november
A19: 62 | B19: Formulas > Trace Dependent | C19: Formules > Repérer les dépendants | D19: 12 | E19: déc | F19: décembre | G19: dec | H19: december
A20: 63 | B20: Displays arrows to the cells using this formula | C20: Affiche des flèches vers les cellules qui utilisent cette formule
A21: 65 | B21: The 'fx' button to the left of the formula bar pops up a window with details and results of the selected formula | C21: Le bouton 'fx' à gauche de la barre de formules ouvre une fenêtre avec les détails et résultats de la formule sélectionnée
A22: 67 | B22: Use: click on a cell containing a formula then click on 'fx'. | C22: Utilisation : cliquez sur une cellule contenant une formule puis cliquez sur 'fx'.
A23: 68 | B23: In case of multiple functions used inside the formula, click on the desired function before pressing 'fx'. | C23: Dans le cas où plusieurs fonctions sont utilisées dans la formule, cliquez sur la fonction désirée avant d’appuyer sur 'fx'. | E23: Status column
A24: 100 | B24: Logical functions | C24: Fonctions logiques | H24: Active | I24: Actif(ve)
A25: 101 | B25: IF | AND | OR | C25: SI | ET | OU | H25: Maternity leave | I25: Congé maternité
A26: 110 | B26: Products | C26: Produits | H26: Pre-retirement | I26: Pré-retraite
A27: 115 | B27: Unit price | C27: Prix unitaire | H27: Training | I27: Stagiaire
A28: 120 | B28: cost | C28: Coût | I28: Sick Leave | J28: Congé maladie
A29: 125 | B29: Last sale | C29: Dernière vente | I29: Retired | J29: Retraité
A30: 130 | B30: Qty | C30: Qté | I30: Inactive | J30: Inactif(ve)
A31: 135 | B31: Logical tests | C31: Tests logiques
A32: 140 | B32: Average | C32: Moyenne
A33: 145 | B33: Threshold | C33: Seuil
A34: 150 | B34: Absolute and relative cell references | C34: Références absolues et relatives de cellule
A35: 155 | B35: RELATIVE REFERENCE | C35: RÉFÉRENCE RELATIVE
A36: 156 | B36: Both the row or the column can be modified when copying the formula | C36: La ligne ou la colonne peuvent être modifiées lors de la copie de la formule
A37: 160 | B37: ABSOLUTE REFERENCE | C37: RÉFÉRENCE ABSOLUE
A38: 162 | B38: The reference is locked. It will always point to that cell. | C38: La référence est verrouillée. Elle pointera toujours vers cette cellule.
A39: 165 | B39: MIXED REFERENCE | C39: RÉFÉRENCE MIXTE
A40: 167 | B40: Either the row or the column reference is locked. Only the free dimension can be modified. | C40: Soit la ligne, soit la référence colonne est verrouillée. Seule la dimension libre peut être modifiée.
A41: 170 | B41: Press F4 while typing the cell refernce to toggle between relative, absolute or mixed reference | C41: Appuyez sur F4 pendant la saisie de la référence pour passer de relative à absolue ou mixte
...

Sheet BASES
A1: FRANÇAIS | C1: {=TranslateTxt(10)} -> Fondamentaux d'une formule | J1: {=TranslateTxt(30)} -> Exemples
C3: =_xlfn.FORMULATEXT(J3) -> =2.5*2*2 | D3: {=TranslateTxt(15)} -> Il faut commencer par le signe '=' | J3: =2.5*2*2 -> 10 | K3: =2*2+1 -> 5 | L3: =2*(2+1) -> 6
C4: =_xlfn.FORMULATEXT(K3) -> =2*2+1 | D4: {=TranslateTxt(16)} -> Excel peut servir de calculatrice
C5: =_xlfn.FORMULATEXT(L3) -> =2*(2+1) | D5: {=TranslateTxt(17)} -> Attention à l’utilisation de « ( » et « ) »
C7: =_xlfn.FORMULATEXT(J7) -> =$J$1 | D7: {=TranslateTxt(20)} -> Liens vers le contenu de la cellule | J7: =$J$1 -> Exemples
C10: =_xlfn.FORMULATEXT(L10) -> =J10+K10 | D10: {=TranslateTxt(40)} -> Ajout des valeurs de cellules | J10: 10 | K10: 20 | L10: =J10+K10 -> 30
C13: =_xlfn.FORMULATEXT(J13) -> =SOMME(J10;K10) | D13: {=TranslateTxt(45)} -> La fonction SOMME pour ajouter les valeurs des cellules | J13: =SUM(J10,K10) -> 30
C16: =_xlfn.FORMULATEXT(J16) -> =SOMME(J10:L10) | D16: {=TranslateTxt(48)} -> La fonction SOMME additionne toutes les valeurs de cellules dans une plage | J16: =SUM(J10:L10) -> 60
C19: =_xlfn.FORMULATEXT(P19) -> =MOYENNE(J19:O19) | D19: {=TranslateTxt(50)} -> Calcule la valeur moyenne d’une plage de cellules | J19: 1 | K19: 2 | L19: 3 | M19: 4 | N19: 5 | O19: 6 | P19: =AVERAGE(J19:O19) -> 3.5
C21: =_xlfn.FORMULATEXT(N21) -> =MAX(K22:K28) | D21: {=TranslateTxt(270)} -> Trouve la valeur max d'une plage | J21: Produits | K21: Prix unitaire | M21: Prix Max | N21: =MAX(K22:K28) -> 660
J22: Geforce RTX 3060 | K22: 325
C23: =_xlfn.FORMULATEXT(N23) -> =MIN(K22:K28) | D23: {=TranslateTxt(275)} -> Trouve la valeur min d'une plage | J23: Geforce RTX 3070 | K23: 390 | M23: Prix Min. | N23: =MIN(K22:K28) -> 325
J24: Geforce RTX 4070 | K24: 450
C25: =_xlfn.FORMULATEXT(M27) -> ="Prix moyen="&N25&", min="&N23&",max="&N21 | J25: Geforce RTX 4080 | K25: 510 | M25: Prix Moyen | N25: =AVERAGE(K22:K28) -> 470
C26: {=TranslateTxt(280)} -> Concaténer des chaînes de caractères avec des nombres dans une formule | J26: Geforce RTX 4090 | K26: 660
C27: =_xlfn.FORMULATEXT(M29) -> =CONCAT(M21;": ";N21;" - ";M23;": ";N23;" - ";M25;": ";N25) | J27: Radeon 7900 | K27: 540 | M27: ="Prix moyen="&N25&", min="&N23&",max="&N21 -> Prix moyen=470, min=325,max=660
J28: Radeon 6700 | K28: 415
M29: =_xlfn.CONCAT(M21,": ",N21," - ",M23,": ",N23," - ",M25,": ",N25) -> Prix Max: 660 - Prix Min.: 325 - Prix Moyen: 470
C30: {=TranslateTxt(55)} -> Cliquez dans la barre de formule pour voir les cellules utilisées dans cette formule
C37: {=TranslateTxt(60)} -> Formules > Repérer les antécédents
C38: {=TranslateTxt(61)} -> Affiche des flèches vers les cellules utilisées dans la formule
C43: {=TranslateTxt(62)} -> Formules > Repérer les dépendants
C44: {=TranslateTxt(63)} -> Affiche des flèches vers les cellules qui utilisent cette formule
C57: {=TranslateTxt(65)} -> Le bouton 'fx' à gauche de la barre de formules ouvre une fenêtre avec les détails et résultats de la formule sélectionnée
C58: {=TranslateTxt(67)} -> Utilisation : cliquez sur une cellule contenant une formule puis cliquez sur 'fx'.
C59: {=TranslateTxt(68)} -> Dans le cas où plusieurs fonctions sont utilisées dans la formule, cliquez sur la fonction désirée avant d’appuyer sur 'fx'.

Sheet REFERENCES
C1: {=TranslateTxt(150)} -> Références absolues et relatives de cellule
B2: A23 | C2: {=TranslateTxt(155)} -> RÉFÉRENCE RELATIVE | E2: {=TranslateTxt(156)} -> La ligne ou la colonne peuvent être modifiées lors de la copie de la formule
B3: $A$23 | C3: {=TranslateTxt(160)} -> RÉFÉRENCE ABSOLUE | E3: {=TranslateTxt(162)} -> La référence est verrouillée. Elle pointera toujours vers cette cellule.
B4: $A23 or A$23 | C4: {=TranslateTxt(165)} -> RÉFÉRENCE MIXTE | E4: {=TranslateTxt(167)} -> Soit la ligne, soit la référence colonne est verrouillée. Seule la dimension libre peut être modifiée.
B5: {=TranslateTxt(170)} -> Appuyez sur F4 pendant la saisie de la référence pour passer de relative à absolue ou mixte
B7: 1 | C7: =B7+1 -> 2 | D7: =_xlfn.FORMULATEXT(C7) -> =B7+1
B8: 2 | C8: =B8+1 -> 3 | D8: =_xlfn.FORMULATEXT(C8) -> =B8+1
B9: 3 | C9: =B9+1 -> 4 | D9: =_xlfn.FORMULATEXT(C9) -> =B9+1
B10: 4 | C10: =B10+1 -> 5 | D10: =_xlfn.FORMULATEXT(C10) -> =B10+1
B11: 5 | C11: =B11+1 -> 6 | D11: =_xlfn.FORMULATEXT(C11) -> =B11+1
B12: 6 | C12: =B12+1 -> 7 | D12: =_xlfn.FORMULATEXT(C12) -> =B12+1
D13: {=TranslateTxt(190)} -> Lorsqu’une formule est copiée, elle se souvient de la position relative des cellules utilisées à l’intérieur
B15: 1 | C15: =$B$15+B15 -> 2 | D15: =_xlfn.FORMULATEXT(C15) -> =$B$15+B15
B16: 2 | C16: =$B$15+B16 -> 3 | D16: =_xlfn.FORMULATEXT(C16) -> =$B$15+B16
B17: 3 | C17: =$B$15+B17 -> 4 | D17: =_xlfn.FORMULATEXT(C17) -> =$B$15+B17
B18: 4 | C18: =$B$15+B18 -> 5 | D18: =_xlfn.FORMULATEXT(C18) -> =$B$15+B18
D19: {=TranslateTxt(195)} -> Une référence absolue ne sera pas modifiée lorsqu’elle est copiée ailleurs
B21: 1 | C21: =$B21+1 -> 2 | D21: =_xlfn.FORMULATEXT(C21) -> =$B21+1 | F21: =B$21+1 -> 2 | G21: =_xlfn.FORMULATEXT(F21) -> =B$21+1
B22: 2 | C22: =$B22+1 -> 3 | D22: =_xlfn.FORMULATEXT(C22) -> =$B22+1 | F22: =B$21+1 -> 2 | G22: =_xlfn.FORMULATEXT(F22) -> =B$21+1
B23: 3 | C23: =$B23+1 -> 4 | D23: =_xlfn.FORMULATEXT(C23) -> =$B23+1 | F23: =B$21+1 -> 2 | G23: =_xlfn.FORMULATEXT(F23) -> =B$21+1
B24: 4 | C24: =$B24+1 -> 5 | D24: =_xlfn.FORMULATEXT(C24) -> =$B24+1 | F24: =B$21+1 -> 2 | G24: =_xlfn.FORMULATEXT(F24) -> =B$21+1
D25: {=TranslateTxt(200)} -> Une référence mixte ne bloque qu’une des deux dimensions
H28: {=TranslateTxt(180)} -> TVA | I28: 0.081
D29: 0.1 | F29: Margin | G29: 0.05 | H29: 0.1 | I29: 0.15
B30: {=TranslateTxt(185)&1} -> Montant1 | C30: {=TranslateTxt(185)&2} -> Montant2 | D30: {=TranslateTxt(185)&3} -> Montant3 | E30: TOTAL | F30: {=TranslateTxt(185)&TranslateTxt(187)} -> Montant TTC | G30: ="+"&G29*100&"%" -> +5% | H30: ="+"&H29*100&"%" -> +10% | I30: ="+"&I29*100&"%" -> +15%
B31: 100000 | C31: 5000
B32: 200000 | C32: -10000
B33: 300000 | C33: 5000
B34: 400000 | C34: -10000
B35: 500000 | C35: 5000
B36: 600000 | C36: -10000
B37: 700000 | C37: 5000
B38: 800000 | C38: -10000
B39: 900000 | C39: 5000
B40: 1000000 | C40: -10000
B41: 1100000 | C41: 5000
D47: {=TranslateTxt(260)} -> Calculez la colonne [Montant3] = 10% de [Montant1]
D50: {=TranslateTxt(261)} -> Calculez les totaux sur chaque ligne
D53: {=TranslateTxt(262)} -> Calculez le Montant TTC (=TOTAL+TVA)
D56: {=TranslateTxt(263)} -> Calculez les prévisions en fonction de la marge (=(TOTAL+Marge)+TVA)

Sheet LOGIQUE
C1: {=TranslateTxt(100)} -> Fonctions logiques | H1: {=TranslateTxt(101)} -> SI | ET | OU
B3: {=TranslateMe(196)} -> #NAME?
B4: COND1 | C4: COND2 | D4: =_xlfn.FORMULATEXT(D5) -> =ET(B5;C5) | E4: =_xlfn.FORMULATEXT(E5) -> =OU(B5;C5) | F4: =_xlfn.FORMULATEXT(F5) -> =OUX(B5;C5)
B5: TRUE | C5: TRUE | D5: =AND(B5,C5) -> TRUE | E5: =OR(B5,C5) -> TRUE | F5: =_xlfn.XOR(B5,C5) -> FALSE
B6: {=$B$5:$F$5*1} -> 1 | C6: 1 | D6: 1 | E6: 1 | F6: 0
D7: =$B$6&" * "&$C$6 -> 1 * 1 | E7: =$B$6&" + "&$C$6 -> 1 + 1 | F7: =$B$6&" + "&$C$6 -> 1 + 1
L10: {=TranslateTxt(220)} -> Pour chaque ligne, si la somme des quantités dépasse la moyenne, alors afficher le nombre sinon non. | N10: {=TranslateTxt(225)} -> Afficher le texte 'OUI' si le coût est situé entre 100 et 200 | P10: {=TranslateTxt(230)} -> Afficher les totaux de vente pour tous les produits 'SSD'
B11: {=TranslateTxt(110)} -> Produits | C11: {=TranslateTxt(115)} -> Prix unitaire | D11: {=TranslateTxt(120)} -> Coût | E11: {=TranslateTxt(125)} -> Dernière vente | F11: {=TranslateTxt(130)&1} -> Qté1 | G11: {=TranslateTxt(130)&2} -> Qté2 | H11: {=TranslateTxt(130)&3} -> Qté3 | I11: {=TranslateTxt(130)&4} -> Qté4 | J11: {="Σ"&TranslateTxt(130)} -> ΣQté | L11: {="> "&TranslateTxt(210)} -> > Moyenne | N11: {="100 < "&TranslateTxt(120)&" < 200"} -> 100 < Coût < 200 | P11: {="["&TranslateTxt(110)&"] "&TranslateTxt(231)&" SSD"} -> [Produits] commence par SSD
B12: SSD 500 GB | C12: 120 | D12: 80 | E12: 45631 | F12: 84 | G12: 50 | H12: 21 | I12: 40
B13: SSD 1 TB | C13: 190 | D13: 114 | E13: 45624 | F13: 5 | G13: 3 | H13: 97 | I13: 67
B14: SSD 2 TB | C14: 280 | D14: 168 | E14: 45550 | F14: 98 | G14: 73 | H14: 47 | I14: 40
B15: HDD 2 TB | C15: 150 | D15: 99 | E15: 45585 | F15: 47 | G15: 33 | H15: 89 | I15: 62
B16: HDD 4TB | C16: 189 | D16: 109 | E16: 45628 | F16: 49 | G16: 44 | H16: 51 | I16: 97
B17: HDD 8 TB | C17: 410 | D17: 249 | E17: 45541 | F17: 83 | G17: 83 | H17: 33 | I17: 68
I19: {=TranslateTxt(210)} -> Moyenne
F21: {=TranslateTxt(255)} -> Affiche le No du jour dans la semaine - JOURSEM() | H21: {=TranslateTxt(245)} -> Vérifiez des conditions multiples avec SI.MULTIPLE
B22: {=TranslateTxt(110)} -> Produits | C22: {=TranslateTxt(115)} -> Prix unitaire | D22: {=TranslateTxt(120)} -> Coût | E22: {=TranslateTxt(125)} -> Dernière vente | F22: {=TranslateTxt(256)} -> No du jour de semaine | H22: {=TranslateNameFromDictionnary(1030)} -> SI.MULTIPLE | I22: {=TranslateTxt(251)} -> Affiche P.U. > 200 si [Prix unitaire] est plus grand que 200
B23: SSD 500 GB | C23: 120 | D23: 80 | E23: 45631 | I23: {=TranslateTxt(250)} -> Affiche 'Commence par S' si [Produits] commence par la lettre S
B24: SSD 1 TB | C24: 190 | D24: 114 | E24: 45624 | I24: {=TranslateTxt(252)} -> Affiche Coût < 100 si [Coût] est inférieur à 100
B25: SSD 2 TB | C25: 280 | D25: 168 | E25: 45550
B26: HDD 2 TB | C26: 150 | D26: 99 | E26: 45585
B27: HDD 4TB | C27: 189 | D27: 109 | E27: 45628
B28: HDD 8 TB | C28: 410 | D28: 249 | E28: 45541

Sheet Fct utiles
B1: Fonctions à connaître
A3: DATE
A4: AUJOURDHUI | C4: MAINTENANT
A5: Renvoie la date actuelle. | C5: {=Translatefct(640,1)} -> Renvoie la date et l’heure actuelles.
A6: =TODAY() -> 46106 | C6: =NOW() -> 46106.75
A7: =_xlfn.FORMULATEXT(A6) -> =AUJOURDHUI() | C7: =_xlfn.FORMULATEXT(C6) -> =MAINTENANT()
A9: DATE | C9: ANNEE | E9: MOIS | G9: JOUR
A10: Renvoie une date à partir des valeurs d’année, mois et jour. | C10: Renvoie l’année d’une date. | E10: Renvoie le mois d’une date. | G10: Renvoie le jour d’une date.
A11: =DATE(2023,9,4) -> 45173 | C11: =YEAR(A11) -> 2023 | E11: =MONTH(A11) -> 9 | G11: =DAY(A11) -> 4
A12: =_xlfn.FORMULATEXT(A11) -> =DATE(2023;9;4) | C12: =_xlfn.FORMULATEXT(C11) -> =ANNEE(A11) | E12: =_xlfn.FORMULATEXT(E11) -> =MOIS(A11) | G12: =_xlfn.FORMULATEXT(G11) -> =JOUR(A11)
A14: TEXTE
C15: =_xlfn.FORMULATEXT(C16) -> =GAUCHE(B16:B20;5) | D15: =_xlfn.FORMULATEXT(D16) -> =DROITE(B16:B20;4) | E15: =_xlfn.FORMULATEXT(E16) -> =STXT(B16:B20;5;3) | G15: =_xlfn.FORMULATEXT(G16) -> =TEXTE.APRES(A16:A20;"-";2)
A16: PWR-16-Small | B16: 70056-2343 | C16: {=LEFT(B16:B20,5)} -> 70056 | D16: {=RIGHT(B16:B20,4)} -> 2343 | E16: {=MID(B16:B20,5,3)} -> 6-2 | F16: {=MID(A16:A20,FIND("-",A16:A20)+1,2)} -> 16 | G16: {=_xlfn.TEXTAFTER(A16:A20,"-",2)} -> Small | H16: {=_xlfn.TEXTBEFORE(A16:A20,"-",2)} -> PWR-16
A17: PW-18-Medium | B17: 75023-5774 | C17: 75023 | D17: 5774 | E17: 3-5 | F17: 18 | G17: Medium | H17: PW-18
A18: PW-19-Large | B18: 17451-6655 | C18: 17451 | D18: 6655 | E18: 1-6 | F18: 19 | G18: Large | H18: PW-19
A19: CWS-20-Medium | B19: 54189-2546 | C19: 54189 | D19: 2546 | E19: 9-2 | F19: 20 | G19: Medium | H19: CWS-20
A20: CWTP-21-Large | B20: 45185-7814 | C20: 45185 | D20: 7814 | E20: 5-7 | F20: 21 | G20: Large | H20: CWTP-21
F21: =_xlfn.FORMULATEXT($F$16) -> =STXT(A16:A20;TROUVE("-";A16:A20)+1;2) | H21: =_xlfn.FORMULATEXT($H$16) -> =TEXTE.AVANT(A16:A20;"-";2)
A23: ARRONDI
A24: 0.056027958 | B24: =ROUND(A24,2) -> 0.06 | C24: =ROUNDDOWN(A24,2) -> 0.05 | D24: =ROUNDUP(A24,2) -> 0.06 | F24: 370673 | G24: =MROUND(F24,50000) -> 350000
A25: 0.23374943 | B25: =ROUND(A25,2) -> 0.23 | C25: =ROUNDDOWN(A25,2) -> 0.23 | D25: =ROUNDUP(A25,2) -> 0.24 | F25: 330619 | G25: =MROUND(F25,50000) -> 350000
A26: 0.16695842 | B26: =ROUND(A26,2) -> 0.17 | C26: =ROUNDDOWN(A26,2) -> 0.16 | D26: =ROUNDUP(A26,2) -> 0.17 | F26: 188384 | G26: =MROUND(F26,50000) -> 200000
A27: 0.62011219 | B27: =ROUND(A27,2) -> 0.62 | C27: =ROUNDDOWN(A27,2) -> 0.62 | D27: =ROUNDUP(A27,2) -> 0.63 | F27: 309081 | G27: =MROUND(F27,50000) -> 300000
B28: =_xlfn.FORMULATEXT(B27) -> =ARRONDI(A27;2) | C28: =_xlfn.FORMULATEXT(C27) -> =ARRONDI.INF(A27;2) | D28: =_xlfn.FORMULATEXT(D27) -> =ARRONDI.SUP(A27;2) | G28: =_xlfn.FORMULATEXT(G27) -> =ARRONDI.AU.MULTIPLE(F27;50000)

Sheet EXERCICE
B1: EXERCICE
A4: Produit | B4: Quantité | C4: Prix Unitaire | D4: Nom Client | E4: Date Commande | F4: Ville | G4: Code Produit | AZ4: Montant | BA4: Montant TTC | BB4: 3premiers | BC4: 2derniers | BD4: Nb car. | BE4: Pos. Tiret | BF4: Pos. 2e tiret | BG4: Partie centrale | BH4: Fractionnement code | BK4: Année | BL4: Date livr. Est. | BM4: Expiration | BN4: Frais Livraison | BO4: Taxe recyclage
A5: Stylo bleu | B5: 24 | C5: 2.5 | D5: Martin | E5: 45303 | F5: Lausanne | G5: STY-BLEU-01 | AZ5: =ROUND(B5*C5,0) -> 60 | BA5: =ROUND(AZ5*(1+REFERENCES!$I$28),0) -> 65 | BB5: =LEFT(G5,3) -> STY | BC5: =RIGHT(G5,2) -> 01 | BD5: =LEN(A5) -> 10 | BE5: =SEARCH("-",G5) -> 4 | BF5: =SEARCH("-",G5,BE5+1) -> 9 | BG5: =MID(G5,BE5+1,BF5-BE5-1) -> BLEU | BH5: {=_xlfn.TEXTSPLIT(G5,"-")} -> STY | BI5: BLEU | BJ5: 01 | BK5: =YEAR(E5) -> 2024 | BL5: =E5+30 -> 45333 | BM5: =DATE(BK5+3,MONTH(E5),DAY(E5)) -> 46399 | BN5: =IF(AZ5<70,$F$11,0) -> 20 | BO5: =IF(OR(BJ5="03",BJ5="04"),$F$12,0) -> 0
A6: Cahier A4 | B6: 10 | C6: 4.8 | D6: Dupont | E6: 45306 | F6: Genève | G6: CAH-A4-05 | AZ6: =ROUND(B6*C6,0) -> 48 | BA6: =ROUND(AZ6*(1+REFERENCES!$I$28),0) -> 52 | BB6: =LEFT(G6,3) -> CAH | BC6: =RIGHT(G6,2) -> 05 | BD6: =LEN(A6) -> 9 | BE6: =SEARCH("-",G6) -> 4 | BF6: =SEARCH("-",G6,BE6+1) -> 7 | BG6: =MID(G6,BE6+1,BF6-BE6-1) -> A4 | BH6: {=_xlfn.TEXTSPLIT(G6,"-")} -> CAH | BI6: A4 | BJ6: 05 | BK6: =YEAR(E6) -> 2024 | BL6: =E6+30 -> 45336 | BM6: =DATE(BK6+3,MONTH(E6),DAY(E6)) -> 46402 | BN6: =IF(AZ6<70,$F$11,0) -> 20 | BO6: =IF(OR(BJ6="03",BJ6="04"),$F$12,0) -> 0
A7: Agenda 2024 | B7: 7 | C7: 19.9 | D7: Pascal | E7: 45325 | F7: Fribourg | G7: AGD-2024-07 | AZ7: =ROUND(B7*C7,0) -> 139 | BA7: =ROUND(AZ7*(1+REFERENCES!$I$28),0) -> 150 | BB7: =LEFT(G7,3) -> AGD | BC7: =RIGHT(G7,2) -> 07 | BD7: =LEN(A7) -> 11 | BE7: =SEARCH("-",G7) -> 4 | BF7: =SEARCH("-",G7,BE7+1) -> 9 | BG7: =MID(G7,BE7+1,BF7-BE7-1) -> 2024 | BH7: {=_xlfn.TEXTSPLIT(G7,"-")} -> AGD | BI7: 2024 | BJ7: 07 | BK7: =YEAR(E7) -> 2024 | BL7: =E7+30 -> 45355 | BM7: =DATE(BK7+3,MONTH(E7),DAY(E7)) -> 46421 | BN7: =IF(AZ7<70,$F$11,0) -> 0 | BO7: =IF(OR(BJ7="03",BJ7="04"),$F$12,0) -> 0
A8: Souris USB | B8: 3 | C8: 35 | D8: Laurent | E8: 45342 | F8: Sion | G8: SRS-USB-03 | AZ8: =ROUND(B8*C8,0) -> 105 | BA8: =ROUND(AZ8*(1+REFERENCES!$I$28),0) -> 114 | BB8: =LEFT(G8,3) -> SRS | BC8: =RIGHT(G8,2) -> 03 | BD8: =LEN(A8) -> 10 | BE8: =SEARCH("-",G8) -> 4 | BF8: =SEARCH("-",G8,BE8+1) -> 8 | BG8: =MID(G8,BE8+1,BF8-BE8-1) -> USB | BH8: {=_xlfn.TEXTSPLIT(G8,"-")} -> SRS | BI8: USB | BJ8: 03 | BK8: =YEAR(E8) -> 2024 | BL8: =E8+30 -> 45372 | BM8: =DATE(BK8+3,MONTH(E8),DAY(E8)) -> 46438 | BN8: =IF(AZ8<70,$F$11,0) -> 0 | BO8: =IF(OR(BJ8="03",BJ8="04"),$F$12,0) -> 10
A9: Clavier AZERTY | B9: 4 | C9: 49 | D9: Fontaine | E9: 45350 | F9: Neuchâtel | G9: CLV-AZT-04 | AZ9: =ROUND(B9*C9,0) -> 196 | BA9: =ROUND(AZ9*(1+REFERENCES!$I$28),0) -> 212 | BB9: =LEFT(G9,3) -> CLV | BC9: =RIGHT(G9,2) -> 04 | BD9: =LEN(A9) -> 14 | BE9: =SEARCH("-",G9) -> 4 | BF9: =SEARCH("-",G9,BE9+1) -> 8 | BG9: =MID(G9,BE9+1,BF9-BE9-1) -> AZT | BH9: {=_xlfn.TEXTSPLIT(G9,"-")} -> CLV | BI9: AZT | BJ9: 04 | BK9: =YEAR(E9) -> 2024 | BL9: =E9+30 -> 45380 | BM9: =DATE(BK9+3,MONTH(E9),DAY(E9)) -> 46446 | BN9: =IF(AZ9<70,$F$11,0) -> 0 | BO9: =IF(OR(BJ9="03",BJ9="04"),$F$12,0) -> 10
E11: Frais de livraison | F11: 20 | BG11: ="Traité le: "&TEXT(TODAY(),"JJ-MM-AA") -> Traité le: 25-03-26
E12: Taxe de recyclage | F12: 10
A38: Solution en colonne AZ
